Workbook
Name direpn: RawCurrent!#REF!
Name direpn: Reveral_Potential!#REF!
Name dirlvnv: RawCurrent!$BL$34:$BL$129
Name dirlvnv: Reveral_Potential!$BL$34:$BL$128

Sheet MetaData
A1: Collector | B1: Author who collected data
A2: Filename | B2: Filename(s) from which these traces were extracted. For some cells wherein individual traces were obstructed by noise, multiple IV recordings were used to create the IV relationship. The filenames are listed here strung together with semicolons. For those cells where only a partial IV relationship is present here, i.e. more than 2 consecutive points are missing over entire range from -80mV to +80mV, these are excluded from the IV relationship averages but included in analyses of Steady State Activation.
A3: Capacitance (picoFarads) | B3: Capacitance of the cell collected either from capac.pro or from a part within the abovementioned filename. The filename from which capac was calculated can be found in the Capacitance sheet.
A4: Genotype | B4: SCN4A encoding NaV1.4 pore sequence; AA sequence reported here. NaV1.4+ (scored, WT, is TTX-sensitive) for translated SCN4A sequences reading 1276-MDIMYA-1281 in DIII and 1556-ICLFEITTSAGWDG-1569 in DIV. NaV1.4EPN (TTX-resistant, scored EPN) were mutagenized to reflect D1277E and A1281P in DIII and D1568N in DIV. NaV1.4LVNV (TTX-resistant, scored LVNV) were mutagenized to reflect I1556L, I1561V, D1568N, and G1569V.
A5: CellID | B5: A unique identifier for each cell from which recordings were obtained in the course of this research program. Each tab in this sheet shall bear this identifier to signify from which cell the enclosed current family were recorded. Simply, the CellID is composed of the Genotype (as written above) and the roughly chronological order in which the cell was recorded. There is an additional sheet in this document showing all the recordings which were obtained from each cell, ordered under its CellID.
A6: Em (mV) | B6: Each cell in this row, rightward, describes the time in milliseconds from the onset of the test pulse and therefore the application of the membrane potential indicated most leftward.
B7: Each value in this array represents the raw current in picoAmperes (pA). The values here were exported from Clampfit 10.6 where they were baseline adjusted and potentially filtered (5000Hz).
A8: Erev | B8: This is the observed reversal potential, calculated by solving for zero in the linear range of the current-voltage relationship.
A9: E1/2 | B9: This is the potential at which half of the total current has developed.
A10: E(Imax) | B10: This is the potential at which the total current has developed.
A11: E(tau_m_min) | B11: This is the potential at which the timecourse of activation is fastest (i.e. Tau_m --> 0)
A12: E(tau_h_min) | B12: This is the potential at which the timecoures of inactivation is fastest (i.e. Tau_h -->0)
A13: fitted g: | B13: This is the expected number of active channels as predicted by fitting the IV curve to the equation I = (g*(V-Erev))/(1+exp(-0.3937*z*(V-V1/2))) where z is the apparent gating charge, V1/2=E1/2 as above.
A14: z (apparent gating charge) | B14: This is the apparent gating charge as predicted by fitting the IV curve to the equation I = (g*(V-Erev))/(1+exp(-0.3937*z*(V-V1/2))) where z is the apparent gating charge, V1/2=E1/2 as above.
A15: z* | B15: This is the apparent gating charge as predicted by solving the equation: z = (ln((GNa/Gmax)-1)*KB*T)/(e(V-V1/2)) where GNa is the conductance at that potential, V, Gmax is the maximum conductance observed in the current-voltage protocol, KB is the Boltzmann Constant (1.88e-23 J/K), T is the absolute temperature in K assuming 25ºC, and e is the elementary charge, 1.602e-19 Coulomb.
A18: List of Files in this Folder
A19: Blcorrected Current | B19: BL or Baseline corrected currents accounts for any non-zero variability when the channels are predictably closed between -80 and -50 mV, which may be due to inherent noise or slow capacitive artifact. These corrections are performed by the equation
A20: NormIV | B20: This is a normalized IV with the greatest negative point set as -1, which allows a preview of Steady State Activation and reversal across genotypes.
A21: Current Density | B21: This is an IV curve normalized to the cell's respective capacitance, as calculated by instantaneous maximum capacitive current (I_max, pA) multiplied by the time constant (tau, ms) of its decay, quantity divided by the voltage step which produced the capacitive transient, resulting in capacitance units, picoFarads (pF). The resultant current magnitudes are presented in picoAmps per picoFarad (pA/pF). An example equation might look like: =IF(ISBLANK(BLcorrectedCurrent!G8),"",BLcorrectedCurrent!G8/BLcorrectedCurrent!G$3)
A22: Conductance_Eeq | B22: This is the conductance, G_Na, at the whole cell level, as calculated by GNa = I/(V-Eeq) where Eeq in the definition of driving force in the denominator is the calculated Equilibriu potential (R = 8.314 J/mol*k, T = 22 + 273.15K, z = +1, F = 96.485 J/mol*mV, Na_out = 145, Na_in = 10).
A23: Conductance_Erev | B23: This is the conductance, G_Na, at the whole cell level, as calculated by GNa = I/(V-Erev) where Erev is the observed reversal potential as reported in the file, Reversal_Potential.
A24: Apparent Gating Charge | B24: This is calculated per the equation: z = (ln((GNa/Gmax)-1)*KB*T)/(e(V-V1/2)) where GNa is the conductance at that potential, V, Gmax is the maximum conductance observed in the current-voltage protocol, KB is the Boltzmann Constant (1.88e-23 J/K), T is the absolute temperature in K assuming 25ºC, and e is the elementary charge, 1.602e-19 Coulomb. An example formula might be: =IF(ISBLANK(Conductance_Eeq!B7),"",IF(Conductance_Eeq!B7<0,((LN(ABS(((Conductance_Eeq!B7/MAX(Conductance_Eeq!B$7:B$27)))))*(1.88E-23)*(25+273.15))/(EXP($A8-B$7))),((LN((Conductance_Eeq!B7/MAX(Conductance_Eeq!B$7:B$27))))*(1.88E-23)*(25+273.15))/(EXP($A8-B$7))))
A25: Tau_m_Rise_time | B25: This is the time of the development of the currents plotted against voltage
A26: Tau_h_decay_time | B26: This is the time constant of the decay of the currents plotted against voltage
A27: Tau_m_to_h_ratio | B27: This is the voltage dependent ratio of the onset to decay time constants
A28: Macroscopic Conductance | B28: This is the conductance, G_Na, at the whole cell level. This will be correlated to the predicted unitary conductance from NSNA (g_Na).
A29: IV report | B29: This is the single file which contains Kact, Kinact, V1/2act, and V1/2inact; G_Na, tau_m, tau_h, tau_m/h, z*_apparent_gating_charge, Imax(current density), and Imax(raw current)
A30: Reversal_Potential | B30: These values were calcualted from NormIV using the slope(Voltage,Current) from +10mV to +80mv, the assumed linear portion of the IV relationship, and intercept(Voltage,Current), to produce the ratio of -Intercept/slope, the Reversal Potential.
... A34: IV_Current_Density_Curves | B34: These are the average current densities at each test potential with values of spread included

Sheet RawCurrent
A1: Collector | B1: REdC | C1: REdC | D1: REdC | E1: REdC | F1: REdC | G1: REdC | H1: REdC | I1: REdC | J1: REdC | K1: REdC | L1: REdC | M1: REdC | N1: REdC | O1: REdC | P1: REdC | Q1: REdC | R1: REdC | S1: REdC | T1: REdC | U1: REdC | V1: REdC | W1: REdC | X1: REdC | Y1: REdC | Z1: REdC | AA1: REdC | AB1: REdC | AC1: REdC | AD1: REdC | AE1: REdC | AF1: REdC | AG1: REdC | AH1: REdC | AI1: REdC | AJ1: REdC | AK1: REdC | AL1: REdC | AM1: REdC | AN1: REdC | AO1: REdC | AP1: REdC | AQ1: REdC | AR1: REdC | AS1: REdC | AT1: REdC | AU1: REdC | AV1: REdC | AW1: REdC | AX1: REdC | AY1: REdC | AZ1: REdC | BA1: REdC | BB1: REdC | BC1: REdC | BD1: REdC | BE1: REdC | BF1: REdC | BG1: REdC | BH1: REdC | BI1: REdC | BJ1: REdC | BK1: REdC | BL1: REdC | BM1: REdC | BN1: REdC | BO1: REdC | BP1: REdC | BQ1: REdC | BR1: REdC | BS1: REdC | BT1: REdC | BU1: REdC | BV1: REdC | BW1: REdC | BX1: REdC | BY1: REdC | BZ1: REdC | CA1: REdC | CB1: REdC | CC1: REdC | CD1: REdC
A2: Filename | B2: WT1_REdC_IV_18704034 | C2: WT2_REdC_IV_1.26.2018 WT cell 5 IV' | D2: WT3_REdC_IV_17728035 Final | E2: WT4_REdC_IV_18705015 | F2: WT5_REdC_IV_17728025 Final | G2: WT6_REdC_IV_wt iv final | H2: WT7_REdC_IV_1.26.2018 | I2: WT8_REdC_IV | J2: WT9_REdC_IV_17504013 Final | K2: WT10_REdC_IV_1.26.2018 WT cell 2 IV' -120 conditioning | L2: WT11_REdC_IV_17723017 | M2: WT12_REdC_IV_17721049 Final filtered | N2: WT13_REdC_IV_17723001 | O2: WT14_REdC_IV_19n15007 | P2: WT15_REdC_IV_19825000 | Q2: WT16_REdC_IV_18705033 | R2: WT17_REdC_IV_17721059 | S2: WT19_REdC_IV_19n23000 (-80:-10); WT19_REdC_IV_19n23009 (0:+80) | T2: WT20_REdC_IV_18115016 | U2: WT21_REdC_IV_19o30001 (-80:0),WT21_REdC_IV_19o30004(10:+80) | V2: WT23_REdC_1.19.2018 IV cell 2 WT leak | W2: WT24_REdC_IV_18705003(-80:10),WT24_REdC_IV_18705002(20:+80) | X2: WT25_REdC_IV_18704045 | Y2: WT26_REdC_IV_17809014 | Z2: WT27_REdC_IV_1.23.2018 IV cell 1 WT | AA2: WT28_REdC_IV_1.23.2018 IV cell 1 WT | AB2: WT29_REdC_IV_18o19010 | AC2: WT30_REdC_IV_1.26.2018 WT cell 1 IV p8 20 sweeps | AD2: WT31_REdC_IV_18o07001 | AE2: WT33_REdC_IV_17728018 | AF2: WT38_REdC_IV_19o21015 | AG2: WT39_REdC_IV_17429002 | AH2: WT40_REdC_IV_17810003 | AI2: WT43_REdC_IV_1.26.2018 WT cell 4 IV | AJ2: WT44_REdC_IV_1.14.2018 IV cell 2 NaV1.4 wt | AK2: WT47_REdC_IV_19911011 | AL2: WT48_REdC_IV_19n06031 | AM2: WT50_REdC_IV_19n06011 | AN2: WT53_REdC_IV_17504004 | AO2: WT54_REdC_IV_1.19.2018 IV cell 1 WT | AP2: WT63_REdC_IV_19n07011 | AQ2: WT66_REdC_IV_18704009 | AR2: WT69_REdC_IV_18o18036 | AS2: WT71_REdC_IV_17722009 | AT2: WT74_REdC_IV_0003.abf | AU2: WT75_REdC_IV_0015.abf | AV2: WT76_REdC_IV_0012.abf | AW2: EPN1_REdC_IV_17725093.abf | AX2: EPN2_REdC_IV_17725017.abf | AY2: EPN3_REdC_IV_18115045.abf | AZ2: EPN4_REdC_IV_IV cell 2 NaV1.4 EPN.abf | BA2: EPN5_REdC_IV_17725043.abf | BB2: EPN6_REdC_IV_1.14.2018 IV cell 1 NaV1.4 EPN.abf | BC2: EPN7_REdC_IV_17718015.abf | BD2: EPN9_REdC_IV_17725067.abf | BE2: EPN10_REdC_IV_2016_09_30_0029.abf | BF2: EPN11_REdC_IV_17725020.abf | BG2: EPN12_REdC_IV_1.19.2018 IV cell 1 EPN'.abf | BH2: EPN13_REdC_IV_2016_09_30_0015.abf | BI2: EPN14_REdC_IV_17725071.abf | BJ2: EPN18_REdC_IV_0012.abf | BK2: LVNV1_REdC_IV_17724088.abf | BL2: LVNV2_REdC_IV_17724059.abf;LVNV2_REdC_IV_17724048.abf;LVNV2_REdC_IV_17724046.abf | BM2: LVNV3_REdC_IV_17726022.abf | BN2: LVNV4_REdC_IV_17429000.abf | BO2: LVNV4_REdC_IV_17429001.abf | BP2: LVNV4_REdC_IV_17429002.abf | BQ2: LVNV5_REdC_IV_17724073.abf | BR2: LVNV6_REdC_IV_19915011.abf | BS2: LVNV7_REdC_IV_19d06007.abf | BT2: LVNV8_REdC_IV_17724003.abf;LVNV8_REdC_IV_17724001.abf | BU2: LVNV9_REdC_IV_17724034.abf | BV2: LVNV10_REdC_IV_17726060.abf;LVNV10_REdC_IV_17726061.abf | BW2: LVNV12_REdC_IV_19912002.abf | BX2: LVNV14_REdC_IV_17726099.abf;LVNV14_REdC_IV_17726072.abf;LVNV14_REdC_IV_17726074.abf;LVNV14_REdC_IV_17726083.abf;LVNV14_REdC_IV_17726088.abf;LVNV14_REdC_IV_17726095.abf;LVNV14_REdC_IV_17726098.abf;LVNV14_REdC_IV_17726100.abf | BY2: LVNV15_REdC_IV_17724016.abf | BZ2: LVNV16_REdC_IV_17726035.abf | CA2: LVNV18_REdC_IV_19911028.abf;LVNV18_REdC_IV_19911026.abf;LVNV18_REdC_IV_19911027.abf;LVNV18_REdC_IV_19911029.abf | CB2: LVNV19_REdC_IV_17714002.abf;LVNV19_REdC_IV_17714003.abf | CC2: LVNV20_REdC_IV_17726011.abf | CD2: LVNV21_REdC_IV_17615002.abf;LVNV4_REdC_IV_17615007.abf
A3: Capacitance_Tau*I_0 (picoFarads) | B3: 6.3918005 | C3: 3.1770135 | D3: 12.816808 | E3: 6.4393644 | F3: 4.1415548 | G3: 6.7330415 | H3: 6.1017498 | I3: 5.2679979 | J3: 1.9426926 | K3: 7.2663764 | L3: 9.8133792 | M3: 5.9634417 | N3: 8.6219729 | O3: 6.9784064 | P3: 5.9439751 | Q3: 9.3769842 | R3: 5.7659016 | S3: 4.9435102 | T3: 6.3687978 | U3: 4.2012946 | V3: 1.9422434 | W3: 5.6914978 | X3: 3.5272978 | Y3: 3.3474243 | Z3: 1.9251147 | AA3: 1.9583813 | AB3: 12.688792 | AC3: 4.3809951 | AD3: 6.8273254 | AE3: 2.3971099 | AF3: 3.9005685 | AG3: 4.0726769 | AH3: 7.534553 | AI3: 4.4405214 | AJ3: 2.5034119 | AK3: 5.8217415 | AL3: 5.4120773 | AM3: 3.130868 | AN3: 2.1530792 | AO3: 4.6828832 | AP3: 4.5696121 | AQ3: 5.4771449 | AR3: 4.5332183 | AS3: 6.2772917 | AT3: 7.250766 | AU3: 5.242494 | AV3: 7.8035581 | AW3: 4.3081732 | AX3: 5.9116515 | AY3: 6.3690268 | AZ3: 1.9958043 | BA3: 5.0152047 | BB3: 2.8197356 | BC3: 6.8148694 | BD3: 5.2707788 | BE3: 3.9566497 | BF3: 5.5692707 | BG3: 4.7930427 | BH3: 4.9504883 | BI3: 10.871166 | BJ3: 7.4679809 | BK3: 19.946134 | BL3: 6.4223088 | BM3: 3.691691 | BN3: 3.9347222 | BO3: 3.9347222 | BP3: 3.9347222 | BQ3: 3.6236144 | BR3: 4.5734652 | BS3: 6.0304289 | BT3: 6.5530017 | BU3: 3.7779332 | BV3: 21.360497 | BW3: 5.157873 | BX3: 7.6189258 | BY3: 3.0101941 | BZ3: 4.5653243 | CA3: 2.663605 | CB3: 4.3495177 | CC3: 4.4240435 | CD3: 1.5789424
A4: Genotype | B4: WT | C4: WT | D4: WT | E4: WT | F4: WT | G4: WT | H4: WT | I4: WT | J4: WT | K4: WT | L4: WT | M4: WT | N4: WT | O4: WT | P4: WT | Q4: WT | R4: WT | S4: WT | T4: WT | U4: WT | V4: WT | W4: WT | X4: WT | Y4: WT | Z4: WT | AA4: WT | AB4: WT | AC4: WT | AD4: WT | AE4: WT | AF4: WT | AG4: WT | AH4: WT | AI4: WT | AJ4: WT | AK4: WT | AL4: WT | AM4: WT | AN4: WT | AO4: WT | AP4: WT | AQ4: WT | AR4: WT | AS4: WT | AT4: WT | AU4: WT | AV4: WT | AW4: EPN | AX4: EPN | AY4: EPN | AZ4: EPN | BA4: EPN | BB4: EPN | BC4: EPN | BD4: EPN | BE4: EPN | BF4: EPN | BG4: EPN | BH4: EPN | BI4: EPN | BJ4: EPN | BK4: LVNV | BL4: LVNV | BM4: LVNV | BN4: LVNV | BO4: LVNV | BP4: LVNV | BQ4: LVNV | BR4: LVNV | BS4: LVNV | BT4: LVNV | BU4: LVNV | BV4: LVNV | BW4: LVNV | BX4: LVNV | BY4: LVNV | BZ4: LVNV | CA4: LVNV | CB4: LVNV | CC4: LVNV | CD4: LVNV
A5: CellID | B5: WT1 | C5: WT2 | D5: WT3 | E5: WT4 | F5: WT5 | G5: WT6 | H5: WT7 | I5: WT8 | J5: WT9 | K5: WT10 | L5: WT11 | M5: WT12 | N5: WT13 | O5: WT14 | P5: WT15 | Q5: WT16 | R5: WT17 | S5: WT19 | T5: WT20 | U5: WT21 | V5: WT23 | W5: WT24 | X5: WT25 | Y5: WT26 | Z5: WT27 | AA5: WT28 | AB5: WT29 | AC5: WT30 | AD5: WT31 | AE5: WT33 | AF5: WT38 | AG5: WT39 | AH5: WT40 | AI5: WT43 | AJ5: WT44 | AK5: WT47 | AL5: WT48 | AM5: WT50 | AN5: WT53 | AO5: WT54 | AP5: WT63 | AQ5: WT66 | AR5: WT69 | AS5: WT71 | AT5: WT74 | AU5: WT75 | AV5: WT76 | AW5: EPN1 | AX5: EPN2 | AY5: EPN3 | AZ5: EPN4 | BA5: EPN5 | BB5: EPN6 | BC5: EPN7 | BD5: EPN9 | BE5: EPN10 | BF5: EPN11 | BG5: EPN12 | BH5: EPN13 | BI5: EPN14 | BJ5: EPN18 | BK5: LVNV1 | BL5: LVNV2 | BM5: LVNV3 | BN5: LVNV4 | BO5: LVNV4 | BP5: LVNV4 | BQ5: LVNV5 | BR5: LVNV6 | BS5: LVNV7 | BT5: LVNV8 | BU5: LVNV9 | BV5: LVNV10 | BW5: LVNV12 | BX5: LVNV14 | BY5: LVNV15 | BZ5: LVNV16 | CA5: LVNV18 | CB5: LVNV19 | CC5: LVNV20 | CD5: LVNV21
A6: Em (mV)
A7: -80 | B7: 190.76965 | C7: -38.082722 | D7: 111.41831 | E7: -95.995209 | F7: 155.65625 | G7: 17.611221 | H7: -16.637297 | I7: 30.267597 | J7: 47.287292 | K7: 22.380414 | L7: 13.67998 | M7: -56.523018 | N7: 30.702393 | O7: -39.011265 | P7: 30.517212 | Q7: 25.286552 | R7: 25.98131 | S7: -23.77593 | T7: 19.610031 | U7: 20.291504 | V7: 10.700874 | W7: 15.000076 | X7: -17.044338 | Y7: 0.57379436 | Z7: 12.395504 | AA7: 8.7450314 | AB7: -38.070217 | AC7: -33.90303 | AD7: 37.17704 | AE7: -31.798643 | AF7: -29.227514 | AG7: 19.441357 | AH7: -43.958023 | AI7: -11.832676 | AJ7: -26.075401 | AK7: -14.539673 | AL7: -22.015884 | AM7: 10.512619 | AN7: 13.88121 | AO7: -16.739033 | AP7: 6.2398911 | AQ7: 14.867638 | AR7: -16.475477 | AS7: -18.079044 | AT7: -16.791512 | AU7: 5.9388561 | AV7: 8.5445948 | AW7: 41.118073 | AX7: -42.305527 | AY7: 15.104832 | AZ7: 9.1045685 | BA7: 0.7701985 | BC7: 1.7952862 | BD7: 34.812439 | BF7: 9.4449739 | BG7: 40.782829 | BH7: -9.1678543 | BI7: 30.844509 | BJ7: 1.0223389 | BK7: -31.821026 | BL7: 4.2073364 | BM7: -9.2414932 | BN7: 19.627762 | BO7: 26.350861 | BP7: 14.298252 | BQ7: 26.83842 | BR7: 3.9710299 | BS7: -1.7510399 | BT7: 10.474659 | BU7: 4.539978 | BV7: -8.6604107 | BW7: 10.029883 | BX7: 0.24005935 | BY7: -22.649155 | BZ7: 15.437969 | CA7: -1.2481499 | CB7: -0.30469561 | CC7: -21.54489 | CD7: 0.7101078
A8: =A7+10 -> -70 | B8: -171.66585 | C8: 33.026848 | D8: 115.29895 | E8: -68.263824 | F8: 160.56778 | G8: 14.131691 | H8: -20.268801 | I8: 44.698574 | J8: -45.067284 | K8: 26.269494 | L8: 15.732279 | M8: 59.81398 | N8: 33.830627 | O8: 26.139236 | P8: 25.16333 | Q8: 37.043163 | R8: 25.273336 | S8: -23.960991 | T8: 23.278015 | U8: 17.507446 | V8: 11.296059 | W8: -18.267426 | X8: -16.423042 | Y8: -11.281967 | Z8: -11.709466 | AA8: -9.1299829 | AB8: 31.74218 | AC8: 29.896389 | AD8: 30.940903 | AE8: 31.406363 | AF8: 33.751648 | AG8: 14.729855 | AH8: 28.689064 | AI8: -20.094986 | AJ8: -20.876797 | AK8: 14.698364 | AL8: 11.444077 | AM8: -10.280327 | AN8: 16.81218 | AO8: 17.077759 | AP8: 10.534286 | AQ8: 20.110359 | AR8: 9.623517 | AS8: 15.404831 | AT8: 11.100632 | AU8: 16.950634 | AV8: 10.316705 | AW8: 59.056641 | AX8: 48.78038 | AY8: 2.6458677 | AZ8: 12.502655 | BA8: -0.70763938 | BC8: -1.9563847 | BD8: -15.45997 | BE8: -30.331871 | BF8: 16.939358 | BG8: -28.505442 | BH8: -11.046104 | BI8: 12.989249 | BJ8: -2.456665 | BK8: -27.163811 | BL8: 3.8799591 | BM8: 9.6204376 | BN8: 29.478508 | BO8: -17.55418 | BP8: 17.208508 | BQ8: 45.156176 | BR8: -27.255146 | BS8: -22.568684 | BT8: 12.265465 | BU8: -26.15921 | BV8: -0.13907592 | BW8: 12.668966 | BX8: -0.083151994 | BY8: -29.59433 | BZ8: 8.2727127 | CA8: 4.420887 | CB8: -1.1887609 | CC8: 21.049981 | CD8: 0.57384682
A9: =A8+10 -> -60 | B9: -162.92908 | C9: 46.089645 | D9: 137.60059 | E9: -51.569031 | F9: -155.3934 | G9: 20.464401 | H9: 18.731956 | I9: 56.624718 | J9: -42.332661 | K9: 22.876003 | L9: 17.366949 | M9: -58.146667 | N9: 42.433403 | O9: 20.137268 | P9: -37.317383 | Q9: 54.268295 | R9: 18.552017 | S9: -20.609144 | T9: 20.08493 | U9: 20.66629 | V9: 8.8187189 | W9: -20.411911 | X9: -18.404255 | Y9: -41.645367 | Z9: -10.76155 | AA9: -10.973408 | AB9: -26.799416 | AC9: 40.667648 | AD9: 26.922426 | AE9: -37.719452 | AF9: -33.349766 | AG9: 24.774479 | AH9: -43.324783 | AI9: -15.681759 | AJ9: -26.355125 | AK9: -13.343506 | AL9: 12.537666 | AM9: -10.390549 | AN9: 17.326218 | AO9: 17.948112 | AP9: 14.251709 | AQ9: -19.040585 | AR9: -13.309686 | AS9: 13.630144 | AT9: 11.519299 | AU9: 19.348476 | AV9: 17.988856 | AW9: 57.690598 | AX9: -42.185089 | AY9: 20.827138 | AZ9: 16.399223 | BA9: -2.2873208 | BD9: -20.766243 | BE9: -33.498245 | BF9: 17.19978 | BG9: -17.571178 | BH9: -11.433083 | BI9: 17.130564 | BJ9: 2.8533936 | BK9: -9.9904327 | BL9: 4.8379059 | BM9: -14.6852 | BN9: -25.364346 | BO9: 22.414371 | BP9: 23.8046 | BQ9: 4.9353991 | BR9: -16.538264 | BS9: 8.7991337 | BT9: 18.091478 | BU9: 13.753098 | BV9: -6.2929236 | BW9: 12.644696 | BX9: -0.45743267 | BY9: 33.786915 | BZ9: -12.530197 | CA9: 9.1283264 | CB9: 2.2975184 | CC9: 1.1692719 | CD9: 6.9348526
A10: =A9+10 -> -50 | B10: -226.80325 | C10: -54.87788 | D10: 140.14464 | E10: 71.776764 | F10: 140.92172 | G10: 20.482613 | H10: -20.800121 | I10: 70.137947 | J10: -38.526951 | K10: -27.470944 | L10: 18.865856 | M10: -52.948753 | N10: -56.922905 | O10: -26.917946 | P10: 26.394958 | Q10: 55.16745 | R10: 22.545647 | S10: -22.831842 | T10: -20.091751 | U10: -24.146362 | V10: 12.603499 | W10: 16.115555 | X10: -24.308678 | Y10: -30.488968 | Z10: 15.833859 | AA10: 16.118307 | AB10: 30.513823 | AC10: 48.586262 | AD10: 30.18515 | AE10: -32.131058 | AF10: 36.315517 | AG10: -16.914677 | AH10: 51.000801 | AI10: -11.294518 | AJ10: 11.057049 | AK10: -13.158752 | AL10: 16.876205 | AM10: 10.117264 | AN10: 15.720139 | AO10: 23.629364 | AP10: 11.452675 | AQ10: -15.276928 | AR10: -15.979816 | AS10: -12.060822 | AT10: -10.750061 | AU10: 23.458666 | AV10: 11.919772 | AW10: 56.702957 | AX10: 52.471359 | AY10: 14.47889 | AZ10: 20.141457 | BA10: 2.2247616 | BC10: -0.85724068 | BD10: 24.365973 | BE10: -38.28648 | BF10: 25.163654 | BG10: -26.465431 | BH10: -14.881248 | BI10: 19.978123 | BK10: 6.44196 | BL10: 6.96241 | BM10: 15.417564 | BN10: 42.420765 | BO10: 26.369583 | BP10: 30.19091 | BQ10: -1.7255907 | BR10: 16.92723 | BS10: -4.7879814 | BT10: 2.4568278 | BV10: -0.23663012 | BW10: 13.602301 | BX10: 0.20408392 | BY10: -25.467636 | BZ10: 12.947136 | CA10: 7.1786079 | CB10: 1.6076042 | CC10: 21.47349 | CD10: 5.0449333
A11: =A10+10 -> -40 | B11: -233.67419 | C11: -68.366135 | D11: 160.03194 | E11: 85.475784 | F11: -138.19176 | G11: -41.483425 | H11: -17.177612 | I11: 74.516884 | J11: 50.989788 | K11: -29.63067 | L11: 15.619484 | M11: 83.433205 | N11: 38.839844 | O11: 30.332443 | P11: -26.984131 | Q11: 78.548668 | R11: 25.605196 | S11: -135.62675 | T11: -50.433182 | U11: 15.687103 | V11: 19.471436 | W11: 19.121902 | X11: 22.462479 | Y11: -16.597111 | Z11: -17.817333 | AA11: -16.132486 | AB11: 36.179276 | AC11: -51.838799 | AD11: -44.928062 | AE11: -46.703018 | AF11: 35.703976 | AG11: 24.218544 | AH11: 60.956314 | AI11: -21.064308 | AJ11: -24.392048 | AK11: -18.65921 | AL11: 18.516556 | AM11: -12.248024 | AN11: -18.766068 | AO11: 30.22612 | AP11: 15.924454 | AQ11: 15.599106 | AR11: 14.555052 | AS11: -14.808867 | AT11: 14.288047 | AU11: 22.212599 | AV11: 8.4954165 | AW11: 66.312759 | AX11: -108.06432 | AY11: -47.196037 | AZ11: 24.875542 | BA11: 21.409799 | BB11: 38.213448 | BC11: 1.0183392 | BD11: 27.722305 | BE11: -33.722843 | BF11: 23.176676 | BG11: 33.484962 | BH11: -11.16568 | BI11: 16.488146 | BJ11: -1.4190674 | BK11: 22.240836 | BL11: -7.4497604 | BM11: 17.199654 | BN11: 51.53157 | BO11: 35.861702 | BP11: 24.928261 | BQ11: -7.7258167 | BR11: -28.523665 | BS11: -19.513441 | BT11: 23.419307 | BU11: 11.489197 | BV11: 18.878919 | BW11: -10.953957 | BX11: 0.096441392 | BY11: 18.903748 | BZ11: 13.765366 | CA11: -9.1383018 | CB11: -12.755957 | CC11: 22.431485 | CD11: 8.2182045
A12: =A11+10 -> -30 | B12: -562.63379 | C12: -305.21802 | D12: 121.36874 | E12: -237.42429 | F12: -292.47778 | G12: -484.19617 | H12: -57.327091 | I12: -461.92447 | J12: -77.403938 | K12: -135.93788 | L12: -51.563049 | M12: -123.19592 | N12: -152.19093 | O12: -72.070831 | P12: -27.037659 | Q12: 86.457458 | R12: -29.138489 | S12: -454.5679 | T12: -291.55896 | U12: -63.230278 | V12: -30.792702 | W12: -37.749557 | X12: -62.566238 | Y12: -38.986206 | Z12: -65.893044 | AA12: -64.939514 | AB12: -63.864861 | AC12: -230.68094 | AD12: 25.742115 | AE12: -72.531403 | AF12: -61.676414 | AG12: -46.191559 | AH12: 54.524734 | AI12: -52.004047 | AJ12: -48.869453 | AK12: -49.552673 | AL12: 18.496193 | AM12: 15.208687 | AN12: -26.673187 | AO12: -69.152618 | AP12: 18.414497 | AQ12: 24.081665 | AR12: -17.442492 | AS12: 14.48137 | AT12: -9.2085368 | AU12: 27.224987 | AV12: -23.530859 | AW12: 63.772598 | AX12: -176.52023 | AY12: -261.98624 | AZ12: 29.179138 | BA12: -11.889108 | BB12: 28.421265 | BC12: -24.025099 | BD12: 49.736904 | BE12: -42.071312 | BF12: 20.988607 | BG12: -66.571709 | BH12: -22.331329 | BI12: 15.493667 | BJ12: -4.0130615 | BK12: 40.292474 | BL12: -44.326202 | BM12: -17.924332 | BN12: 57.07761 | BO12: -46.299343 | BP12: -52.876167 | BQ12: 5.5840759 | BR12: -31.296947 | BS12: -106.94248 | BT12: -3.8474223 | BU12: -26.756454 | BV12: -27.843135 | BW12: -10.085375 | BX12: -8.9122577 | BY12: -15.705162 | BZ12: 17.45919 | CA12: -21.437691 | CB12: -25.685047 | CC12: -25.302629 | CD12: -14.080004
A13: =A12+10 -> -20 | B13: -2397.3298 | C13: -744.36609 | D13: -1207.577 | E13: -1482.4885 | F13: -1251.6573 | G13: -1898.1127 | H13: -287.05487 | I13: -1871.9958 | J13: -420.89276 | K13: -1070.9853 | L13: -260.91531 | M13: -1189.7117 | N13: -1496.2181 | O13: -489.01227 | P13: -60.339264 | Q13: -302.22839 | R13: -154.92546 | S13: -836.75201 | T13: -611.81952 | U13: -339.76233 | V13: -146.25339 | W13: -152.59921 | X13: -255.16618 | Y13: -166.98201 | Z13: -194.26573 | AA13: -192.86827 | AB13: -224.65088 | AC13: -1058.6348 | AD13: -26.66634 | AE13: -209.24583 | AF13: -177.58772 | AG13: -211.62915 | AH13: -127.55922 | AI13: -164.69551 | AJ13: -122.71474 | AK13: -216.9283 | AL13: 29.612236 | AM13: -55.189442 | AN13: -117.27725 | AO13: -143.76385 | AP13: -33.396717 | AQ13: -64.215515 | AR13: -52.757385 | AS13: -65.53479 | AT13: -29.838947 | AU13: -123.14284 | AV13: -34.676418 | AW13: -193.72835 | AX13: -1028.0876 | AY13: -711.27582 | AZ13: -137.07388 | BA13: -123.29467 | BB13: -68.906052 | BC13: -167.45419 | BD13: -84.261993 | BE13: -89.574295 | BF13: -25.888304 | BG13: -151.81161 | BH13: -41.264786 | BI13: -35.685833 | BJ13: -34.9884 | BK13: -168.19778 | BL13: -216.24312 | BM13: -90.616997 | BN13: -124.14526 | BO13: -198.77666 | BP13: -202.0125 | BQ13: -117.18174 | BR13: -115.23433 | BS13: -393.85552 | BT13: -81.59789 | BU13: -71.24678 | BV13: -94.669548 | BW13: -21.702017 | BX13: -107.23216 | BY13: -52.279221 | BZ13: -34.162827 | CA13: -41.988726 | CB13: -49.266872 | CC13: -42.592026 | CD13: -38.849658
A14: =A13+10 -> -10 | B14: -5148.9229 | C14: -943.19275 | D14: -2815.7039 | E14: -3247.7295 | F14: -2852.8438 | G14: -2034.245 | H14: -1103.6113 | I14: -1983.2209 | J14: -1453.642 | K14: -2730.798 | L14: -718.46985 | M14: -2480.6167 | N14: -1585.7062 | O14: -1232.6805 | P14: -149.80408 | Q14: -950.41388 | R14: -604.68292 | S14: -1002.8686 | T14: -832.70947 | U14: -879.12036 | V14: -475.20676 | W14: -398.09399 | X14: -576.92639 | Y14: -431.46927 | Z14: -398.27802 | AA14: -397.4617 | AB14: -581.289 | AC14: -1467.3821 | AD14: -100.97643 | AE14: -315.20624 | AF14: -451.6308 | AG14: -438.58719 | AH14: -361.45102 | AI14: -316.38937 | AJ14: -330.66254 | AK14: -395.48407 | AL14: -133.01086 | AM14: -213.5128 | AN14: -362.56616 | AO14: -214.63589 | AP14: -100.4772 | AQ14: -114.71774 | AR14: -91.334015 | AS14: -137.94876 | AT14: -145.80545 | AU14: -407.56503 | AV14: -102.1035 | AW14: -669.44629 | AX14: -1624.0811 | AY14: -1109.4822 | AZ14: -408.35703 | BA14: -371.5149 | BB14: -135.20973 | BC14: -358.00244 | BD14: -249.98653 | BE14: -289.8631 | BF14: -114.9137 | BG14: -317.47189 | BH14: -107.73336 | BI14: -102.38145 | BJ14: -84.21325 | BK14: -685.30559 | BL14: -396.1196 | BM14: -286.48669 | BN14: -381.41376 | BO14: -404.91248 | BP14: -426.14517 | BQ14: -273.69556 | BR14: -302.24682 | BS14: -704.89133 | BT14: -205.48572 | BV14: -188.71367 | BW14: -65.527306 | BX14: -198.95404 | BY14: -163.96584 | BZ14: -69.968018 | CA14: -92.469162 | CB14: -84.843249 | CC14: -97.708736 | CD14: -80.026192
A15: =A14+10 -> 0 | B15: -6839.8921 | C15: -1008.7758 | D15: -2856.8955 | E15: -3896.0374 | F15: -3183.1965 | G15: -1825.8131 | H15: -1821.0068 | I15: -1828.7771 | J15: -1923.505 | K15: -3621.6972 | L15: -1009.3801 | M15: -2639.6238 | N15: -1491.8091 | O15: -1442.5521 | P15: -823.22522 | Q15: -1382.2616 | R15: -1120.5664 | S15: -1033.1877 | T15: -880.74573 | U15: -1022.7136 | V15: -670.17053 | W15: -724.41901 | X15: -807.79218 | Y15: -685.4137 | Z15: -581.47174 | AA15: -580.89197 | AB15: -724.89862 | AC15: -1578.1072 | AD15: -256.97211 | AE15: -320.15948 | AF15: -604.30267 | AG15: -557.89526 | AH15: -548.54071 | AI15: -475.94852 | AJ15: -446.95462 | AK15: -465.76852 | AL15: -295.42032 | AM15: -337.21466 | AN15: -503.70953 | AO15: -271.61261 | AP15: -185.68323 | AQ15: -170.20895 | AR15: -122.84799 | AS15: -190.19072 | AT15: -195.0998 | AU15: -602.43069 | AV15: -168.94425 | AW15: -1072.4928 | AX15: -1878.309 | AY15: -1228.7164 | AZ15: -659.70276 | BA15: -592.71122 | BB15: -223.53677 | BC15: -423.67877 | BD15: -417.02496 | BE15: -353.17331 | BF15: -190.22089 | BG15: -538.21832 | BH15: -133.52858 | BI15: -160.35138 | BJ15: -140.06041 | BK15: -1056.2832 | BL15: -539.39111 | BM15: -393.20926 | BN15: -469.97903 | BO15: -524.85577 | BP15: -503.32852 | BQ15: -388.27606 | BR15: -435.5731 | BS15: -767.74269 | BT15: -308.23785 | BU15: -277.70749 | BV15: -244.43027 | BW15: -185.14961 | BX15: -287.69546 | BY15: -235.67972 | BZ15: -102.05129 | CA15: -146.32566 | CB15: -103.95366 | CC15: -136.86387 | CD15: -121.84972
A16: =A15+10 -> 10 | B16: -7092.2485 | C16: -922.76788 | D16: -3050.2351 | E16: -3630.1912 | F16: -3554.1753 | G16: -1651.6892 | H16: -2016.9824 | I16: -1654.9325 | J16: -1848.8416 | K16: -3719.7826 | L16: -1056.1161 | M16: -2337.2773 | N16: -1396.8855 | O16: -1310.6688 | P16: -1621.3936 | Q16: -1498.8773 | R16: -1223.4143 | S16: -982.97394 | T16: -791.30994 | U16: -916.46155 | V16: -829.6817 | W16: -834.70148 | X16: -800.36884 | Y16: -851.74561 | Z16: -668.92657 | AA16: -667.23297 | AB16: -693.53595 | AC16: -1461.9618 | AD16: -567.59631 | AE16: -571.19672 | AF16: -623.00122 | AG16: -582.72412 | AH16: -643.32318 | AI16: -488.23602 | AJ16: -511.00049 | AK16: -451.18906 | AL16: -380.48047 | AM16: -351.60712 | AN16: -501.33441 | AO16: -287.28729 | AP16: -199.58591 | AQ16: -181.74948 | AR16: -138.13588 | AS16: -205.64948 | AT16: -262.1753 | AU16: -710.62213 | AV16: -196.7885 | AW16: -1259.1644 | AX16: -1871.8953 | AY16: -1174.7263 | AZ16: -719.71606 | BA16: -701.47442 | BB16: -238.64883 | BC16: -425.69693 | BD16: -444.20239 | BE16: -405.83609 | BF16: -241.9574 | BG16: -597.94403 | BH16: -134.95062 | BI16: -163.61597 | BJ16: -166.67174 | BK16: -1253.5961 | BL16: -562.9126 | BM16: -416.1413 | BN16: -473.1669 | BO16: -513.17133 | BP16: -523.55566 | BQ16: -445.91772 | BR16: -465.91847 | BS16: -728.47284 | BT16: -344.93886 | BU16: -299.99445 | BV16: -284.01453 | BW16: -292.68433 | BX16: -324.96004 | BY16: -258.5307 | BZ16: -124.72621 | CA16: -159.93834 | CB16: -106.2161 | CC16: -192.29216 | CD16: -144.70572
A17: =A16+10 -> 20 | B17: -6595.0283 | C17: -794.64447 | D17: -2725.157 | E17: -3109.856 | F17: -3287.6587 | G17: -1389.2926 | H17: -1952.2172 | I17: -1392.9263 | J17: -1525.1219 | K17: -3369.7494 | L17: -895.35974 | M17: -2087.3081 | N17: -1235.6641 | O17: -1125.5763 | P17: -1528.0204 | Q17: -1372.9916 | R17: -1249.885 | S17: -807.98999 | T17: -658.49371 | U17: -787.54889 | V17: -750.84027 | W17: -634.55139 | X17: -688.09424 | Y17: -699.43909 | Z17: -625.48822 | AA17: -600.12512 | AB17: -615.07098 | AC17: -1243.8113 | AD17: -658.771 | AE17: -658.92181 | AF17: -586.526 | AG17: -522.84851 | AH17: -630.79065 | AI17: -422.7742 | AJ17: -455.24445 | AK17: -392.84708 | AL17: -353.31726 | AM17: -342.21588 | AN17: -540.71729 | AO17: -244.36496 | AP17: -179.35275 | AQ17: -168.63774 | AR17: -118.90279 | AS17: -185.95488 | AT17: -238.5333 | AU17: -596.64072 | AV17: -202.67994 | AW17: -1201.7507 | AX17: -1698.6322 | AY17: -1040.5359 | AZ17: -703.51941 | BA17: -675.6666 | BB17: -222.11111 | BC17: -364.97293 | BD17: -404.67123 | BE17: -371.53232 | BF17: -245.05612 | BG17: -636.06451 | BH17: -112.76084 | BI17: -149.82368 | BJ17: -159.86632 | BK17: -1203.5375 | BL17: -475.81396 | BM17: -430.28159 | BN17: -394.93195 | BO17: -379.75455 | BP17: -456.09882 | BQ17: -399.50488 | BR17: -400.39048 | BS17: -624.51744 | BT17: -331.22603 | BU17: -285.41403 | BV17: -236.22112 | BW17: -308.27759 | BX17: -283.22752 | BY17: -207.78125 | BZ17: -105.1202 | CA17: -152.51276 | CB17: -88.964127 | CC17: -191.90972 | CD17: -142.99647
A18: =A17+10 -> 30 | B18: -5687.4316 | C18: -648.8288 | D18: -2189.2019 | E18: -2404.1914 | F18: -2685.7266 | G18: -1121.8213 | H18: -1722.5223 | I18: -1112.3099 | J18: -1004.9916 | K18: -2851.3827 | L18: -712.63458 | M18: -1736.2856 | N18: -998.20929 | O18: -864.55463 | P18: -1279.2218 | Q18: -1149.7452 | R18: -940.711 | S18: -616.20215 | T18: -493.03226 | U18: -630.70245 | V18: -626.42206 | W18: -441.53574 | X18: -562.72913 | Y18: -561.45667 | Z18: -497.43649 | AA18: -476.41949 | AB18: -482.18704 | AC18: -1024.1014 | AD18: -607.61414 | AE18: -580.08673 | AF18: -493.49496 | AG18: -422.57321 | AH18: -487.12152 | AI18: -323.01146 | AJ18: -379.94824 | AK18: -317.12433 | AL18: -300.06409 | AM18: -266.90399 | AO18: -196.75113 | AP18: -140.95973 | AQ18: -142.64706 | AR18: -88.600098 | AS18: -135.84706 | AT18: -205.43173 | AU18: -485.97658 | AV18: -143.26721 | AW18: -1065.4313 | AX18: -1364.326 | AY18: -807.40869 | AZ18: -641.29022 | BA18: -589.92289 | BB18: -185.56741 | BC18: -264.96585 | BD18: -324.63434 | BE18: -303.95657 | BF18: -195.93527 | BG18: -546.90479 | BH18: -89.067299 | BI18: -125.61145 | BJ18: -127.63976 | BK18: -1009.6936 | BL18: -373.62885 | BM18: -329.00354 | BN18: -270.82013 | BO18: -253.63281 | BP18: -340.35126 | BQ18: -341.80386 | BR18: -290.08867 | BS18: -481.48799 | BT18: -264.21355 | BU18: -252.47263 | BV18: -185.02524 | BW18: -297.03244 | BX18: -226.03865 | BZ18: -78.892319 | CA18: -113.46965 | CB18: -75.422123 | CC18: -197.92558 | CD18: -115.43805
A19: =A18+10 -> 40 | B19: -4656.4746 | C19: -478.4819 | D19: -1540.9113 | E19: -1645.0181 | F19: -1896.6946 | G19: -881.79059 | H19: -1425.6462 | I19: -838.86823 | J19: -749.18256 | K19: -2265.1589 | L19: -477.9118 | M19: -1376.5006 | N19: -753.41852 | O19: -607.40216 | P19: -953.48688 | Q19: -840.83594 | R19: -666.32703 | S19: -400.26416 | T19: -324.79901 | U19: -431.85153 | V19: -457.19202 | W19: -258.10297 | X19: -402.88126 | Y19: -405.86627 | Z19: -370.11716 | AA19: -356.10107 | AB19: -348.46387 | AC19: -764.49896 | AD19: -500.44571 | AE19: -427.61899 | AF19: -360.99954 | AG19: -295.56424 | AH19: -319.30109 | AI19: -214.22779 | AJ19: -290.04645 | AK19: -248.35104 | AL19: -216.4332 | AM19: -204.85492 | AO19: -144.62318 | AP19: -90.687744 | AQ19: -104.14737 | AR19: -55.552689 | AS19: -106.99079 | AT19: -148.23588 | AU19: -365.0445 | AV19: -82.150658 | AW19: -820.33386 | AX19: -1030.5537 | AY19: -575.68488 | AZ19: -505.29065 | BA19: -455.95162 | BB19: -164.44008 | BC19: -167.32559 | BD19: -203.3912 | BE19: -229.34854 | BF19: -154.72267 | BG19: -437.56195 | BH19: -64.857704 | BI19: -95.278847 | BJ19: -93.124383 | BK19: -730.40099 | BL19: -267.01703 | BM19: -229.0715 | BN19: -132.93747 | BO19: -126.65548 | BP19: -219.35231 | BQ19: -225.15079 | BR19: -197.6628 | BS19: -334.62321 | BT19: -191.90771 | BU19: -200.74077 | BV19: -127.08911 | BW19: -216.38988 | BX19: -165.4942 | BZ19: -49.511337 | CA19: -66.074249 | CB19: -58.691062 | CC19: -185.23858 | CD19: -88.539479
A20: =A19+10 -> 50 | B20: -3251.8984 | C20: -339.95828 | D20: -907.97327 | E20: -947.44055 | F20: -1099.6511 | G20: -604.71869 | H20: -1116.3372 | I20: -565.50568 | J20: -408.6109 | K20: -1690.3848 | L20: -263.07452 | M20: -1067.0215 | N20: -522.22186 | O20: -324.52899 | P20: -563.71851 | Q20: -549.7464 | R20: -336.25064 | S20: -208.12439 | T20: -198.12004 | U20: -264.93109 | V20: -257.03717 | W20: -108.17475 | X20: -232.65549 | Y20: -227.55463 | Z20: -261.96286 | AA20: -240.83722 | AB20: -231.93523 | AC20: -554.12329 | AD20: -347.03006 | AE20: -240.67331 | AF20: -232.02791 | AG20: -164.74684 | AH20: -165.50941 | AI20: -127.44786 | AJ20: -210.06812 | AK20: -145.31926 | AL20: -135.28442 | AM20: -125.85539 | AO20: -88.84568 | AP20: -45.372005 | AQ20: -99.389832 | AR20: -34.672062 | AS20: -73.590683 | AT20: -88.748457 | AU20: -223.42817 | AV20: -25.683857 | AW20: -572.92242 | AX20: -724.44421 | AY20: -364.37021 | AZ20: -348.86316 | BA20: -307.08362 | BB20: -113.56882 | BC20: -77.726484 | BD20: -102.5919 | BE20: -171.2914 | BF20: -82.873199 | BG20: -310.09155 | BH20: -39.962303 | BI20: -60.910992 | BJ20: -60.714715 | BK20: -449.70571 | BL20: -152.04114 | BM20: -144.60802 | BN20: 26.010376 | BO20: -33.606064 | BP20: -110.65939 | BQ20: -97.324852 | BR20: -100.90076 | BS20: -180.07357 | BT20: -139.52366 | BU20: -156.84818 | BV20: -85.752678 | BW20: -149.1315 | BX20: -95.832199 | BZ20: -20.304924 | CA20: -21.300884 | CB20: -35.833464 | CC20: -145.71615 | CD20: -58.130121
A21: =A20+10 -> 60 | B21: -2144.499 | C21: -226.62744 | D21: -361.76648 | E21: -309.7634 | F21: -234.34177 | G21: -336.21637 | H21: -771.41589 | I21: -323.63321 | J21: 125.53793 | K21: -1124.3509 | L21: -94.210648 | M21: -689.79059 | N21: -269.62152 | O21: -108.61676 | P21: -190.11914 | Q21: -266.0282 | R21: -120.62405 | S21: -62.665543 | T21: -80.242416 | U21: -95.700935 | V21: -132.68298 | W21: 35.365913 | X21: -131.60333 | Y21: -124.2272 | Z21: -108.15429 | AA21: -97.196777 | AB21: -122.37541 | AC21: -320.85156 | AD21: -192.75871 | AE21: -73.873665 | AF21: -127.35618 | AG21: -105.31956 | AH21: -37.514481 | AI21: -35.239529 | AJ21: -126.35247 | AK21: -58.076553 | AL21: -59.786491 | AM21: -53.27367 | AO21: -47.432888 | AP21: -12.950897 | AQ21: -51.178986 | AR21: -18.038111 | AS21: -60.952614 | AT21: -31.461299 | AU21: -102.37182 | AV21: 8.3182931 | AW21: -323.84259 | AX21: -441.62469 | AY21: -176.47252 | AZ21: -219.06757 | BA21: -167.25689 | BB21: -60.4776 | BC21: -19.574495 | BD21: 15.356616 | BE21: -112.92509 | BG21: -178.84828 | BH21: -28.695969 | BI21: -32.347198 | BJ21: -32.180783 | BK21: -203.3766 | BL21: -45.921093 | BM21: -75.851341 | BN21: 104.33966 | BO21: 42.242783 | BP21: 39.705612 | BQ21: 54.804718 | BR21: -4.9272614 | BS21: -27.7149 | BT21: -60.756945 | BU21: -106.32626 | BV21: -24.890846 | BW21: -87.282547 | BX21: -63.460505 | BZ21: -17.59716 | CA21: 24.914406 | CB21: -18.451176 | CC21: -123.25751 | CD21: -30.464689
A22: =A21+10 -> 70 | B22: -1144.597 | C22: -140.51917 | D22: 147.92889 | E22: 229.37862 | F22: 770.33771 | G22: -104.55036 | H22: -501.40994 | I22: -111.70145 | J22: 97.837257 | K22: -664.05889 | L22: 72.979813 | M22: -357.76248 | N22: 84.477432 | O22: 162.68079 | P22: 142.36179 | Q22: 127.28312 | R22: 53.861313 | S22: 115.77434 | T22: 39.731842 | U22: 46.64534 | V22: 38.442307 | W22: 62.457634 | X22: -28.248993 | Y22: 72.75267 | Z22: 54.26025 | AA22: 99.445351 | AB22: 38.938988 | AC22: -157.32355 | AD22: -69.603775 | AE22: 190.94345 | AF22: 54.681156 | AG22: 38.411018 | AH22: 44.114105 | AI22: 17.28804 | AJ22: 36.345245 | AK22: -27.218323 | AL22: 24.330109 | AM22: -13.465996 | AO22: 68.208069 | AP22: 42.579643 | AQ22: 100.93701 | AR22: 38.260361 | AS22: 22.724548 | AT22: 3.383316 | AU22: 41.419144 | AV22: 49.835672 | AW22: 163.58641 | AX22: -184.34254 | AY22: 48.767746 | AZ22: -95.757034 | BA22: -65.934672 | BB22: 37.701508 | BC22: 18.957674 | BD22: 79.794044 | BE22: -33.097481 | BF22: 47.634369 | BG22: -72.145096 | BH22: 22.479187 | BI22: 24.392227 | BJ22: -3.9520264 | BK22: 37.882897 | BL22: 42.616535 | BM22: -25.841217 | BN22: 188.95267 | BO22: 82.328598 | BP22: 86.547409 | BQ22: 120.23207 | BR22: 103.87666 | BS22: 118.43167 | BT22: 25.111635 | BU22: -77.152359 | BV22: 28.859449 | BW22: -28.388851 | BX22: -7.7333037 | BZ22: 65.667252 | CA22: 62.647724 | CB22: 9.7026482 | CC22: -89.168938 | CD22: -9.5503025
A23: =A22+10 -> 80 | B23: -563.39227 | C23: -71.044319 | D23: 421.51035 | E23: 659.38458 | F23: 1423.1299 | G23: 145.27625 | H23: -206.27438 | I23: 76.319641 | J23: 407.4845 | K23: -216.50691 | L23: 193.70471 | M23: 130.40953 | N23: 299.97931 | O23: 349.74463 | P23: 426.1217 | Q23: 212.46526 | R23: 130.46928 | S23: 185.43141 | T23: 110.2263 | U23: 188.91554 | V23: 156.37274 | W23: 103.30631 | X23: 138.78418 | Y23: 148.06905 | Z23: 133.42284 | AA23: 160.06265 | AB23: 133.98877 | AC23: 23.070499 | AD23: 175.93195 | AE23: 370.5127 | AF23: 116.82287 | AG23: 96.877319 | AH23: 63.437653 | AI23: 84.98114 | AJ23: 44.84021 | AK23: 38.297745 | AL23: 72.15625 | AM23: 51.088264 | AO23: 94.566727 | AP23: 65.617554 | AQ23: -30.710976 | AR23: 48.629963 | AS23: 25.64521 | AT23: 61.042763 | AU23: 94.150963 | AV23: 81.961847 | AW23: 227.73148 | AX23: 70.731567 | AY23: 167.87643 | AZ23: 43.886215 | BA23: 75.752099 | BC23: 50.977127 | BD23: 113.49654 | BE23: -40.114674 | BF23: 67.999573 | BG23: 23.614853 | BH23: 21.469254 | BJ23: 26.016233 | BK23: 229.80464 | BL23: 95.75885 | BM23: -22.889008 | BN23: 236.95549 | BO23: 130.75975 | BP23: 127.19286 | BQ23: 199.90555 | BR23: 167.40284 | BS23: 221.79205 | BT23: 70.198331 | BU23: 31.928696 | BV23: 34.018841 | BW23: 46.612862 | BX23: 10.403308 | BZ23: 52.522919 | CA23: 92.819416 | CB23: 12.070749 | CC23: -50.691082 | CD23: 9.1638412
A24: =A23+10 -> 90 | B24: 845.79419 | C24: 45.613106 | K24: 144.39091 | M24: 277.07773 | AC24: 401.61145
A25: =A24+10 -> 100 | B25: 1512.0446 | C25: 88.855515 | K25: 402.32959 | M25: 527.48138 | AC25: 509.87943
A26: =A25+10 -> 110 | B26: 1961.4293 | C26: 134.55762 | K26: 616.82118 | M26: 645.25977 | AC26: 613.67719
A27: =A26+10 -> 120 | B27: 2262.9968
A28: 130 | B28: 2430.0552 | AR28: Recorded_in_AD293 | AV28: Recorded_in_AD293 | AY28: good_cancellation
A29: comment | F29: great_cancellation | BS29: good_cancellation

Sheet NormIV
A1: Collector | B1: =RawCurrent!B1 -> REdC | C1: =RawCurrent!C1 -> REdC | D1: =RawCurrent!D1 -> REdC | E1: =RawCurrent!E1 -> REdC | F1: =RawCurrent!F1 -> REdC | G1: =RawCurrent!G1 -> REdC | H1: =RawCurrent!H1 -> REdC | I1: =RawCurrent!I1 -> REdC | ... CD1: =RawCurrent!CD1 -> REdC
A2: Filename | B2: =RawCurrent!B2 -> WT1_REdC_IV_18704034 | C2: =RawCurrent!C2 -> WT2_REdC_IV_1.26.2018 WT cell 5 IV' | D2: =RawCurrent!D2 -> WT3_REdC_IV_17728035 Final | E2: =RawCurrent!E2 -> WT4_REdC_IV_18705015 | F2: =RawCurrent!F2 -> WT5_REdC_IV_17728025 Final | G2: =RawCurrent!G2 -> WT6_REdC_IV_wt iv final | H2: =RawCurrent!H2 -> WT7_REdC_IV_1.26.2018 | I2: =RawCurrent!I2 -> WT8_REdC_IV | ... CD2: =RawCurrent!CD2 -> LVNV21_REdC_IV_17615002.abf;LVNV4_REdC_IV_17615007.abf
A3: Capacitance_Tau*I_0 (picoFarads) | B3: =RawCurrent!B3 -> 6.3918005 | C3: =RawCurrent!C3 -> 3.1770135 | D3: =RawCurrent!D3 -> 12.816808 | E3: =RawCurrent!E3 -> 6.4393644 | F3: =RawCurrent!F3 -> 4.1415548 | G3: =RawCurrent!G3 -> 6.7330415 | H3: =RawCurrent!H3 -> 6.1017498 | I3: =RawCurrent!I3 -> 5.2679979 | ... CD3: =RawCurrent!CD3 -> 1.5789424
A4: Genotype | B4: =RawCurrent!B4 -> WT | C4: =RawCurrent!C4 -> WT | D4: =RawCurrent!D4 -> WT | E4: =RawCurrent!E4 -> WT | F4: =RawCurrent!F4 -> WT | G4: =RawCurrent!G4 -> WT | H4: =RawCurrent!H4 -> WT | I4: =RawCurrent!I4 -> WT | ... CD4: =RawCurrent!CD4 -> LVNV
A5: CellID | B5: =RawCurrent!B5 -> WT1 | C5: =RawCurrent!C5 -> WT2 | D5: =RawCurrent!D5 -> WT3 | E5: =RawCurrent!E5 -> WT4 | F5: =RawCurrent!F5 -> WT5 | G5: =RawCurrent!G5 -> WT6 | H5: =RawCurrent!H5 -> WT7 | I5: =RawCurrent!I5 -> WT8 | ... CD5: =RawCurrent!CD5 -> LVNV21
A6: Em (mV)
A7: -80 | B7: =IF(ISBLANK(RawCurrent!B7),"",-(RawCurrent!B7/MIN(RawCurrent!B$7:B$28))) -> 0.026898332 | C7: =IF(ISBLANK(RawCurrent!C7),"",-(RawCurrent!C7/MIN(RawCurrent!C$7:C$28))) -> -0.037751424 | D7: =IF(ISBLANK(RawCurrent!D7),"",-(RawCurrent!D7/MIN(RawCurrent!D$7:D$28))) -> 0.036527778 | E7: =IF(ISBLANK(RawCurrent!E7),"",-(RawCurrent!E7/MIN(RawCurrent!E$7:E$28))) -> -0.024639191 | F7: =IF(ISBLANK(RawCurrent!F7),"",-(RawCurrent!F7/MIN(RawCurrent!F$7:F$28))) -> 0.043795322 | G7: =IF(ISBLANK(RawCurrent!G7),"",-(RawCurrent!G7/MIN(RawCurrent!G$7:G$28))) -> 0.0086573748 | H7: =IF(ISBLANK(RawCurrent!H7),"",-(RawCurrent!H7/MIN(RawCurrent!H$7:H$28))) -> -0.0082486077 | I7: =IF(ISBLANK(RawCurrent!I7),"",-(RawCurrent!I7/MIN(RawCurrent!I$7:I$28))) -> 0.015261838 | ... CD7: =IF(ISBLANK(RawCurrent!CD7),"",-(RawCurrent!CD7/MIN(RawCurrent!CD$7:CD$28))) -> 0.0049072544
A8: =A7+10 -> -70 | B8: =IF(ISBLANK(RawCurrent!B8),"",-(RawCurrent!B8/MIN(RawCurrent!B$7:B$28))) -> -0.024204714 | C8: =IF(ISBLANK(RawCurrent!C8),"",-(RawCurrent!C8/MIN(RawCurrent!C$7:C$28))) -> 0.032739534 | D8: =IF(ISBLANK(RawCurrent!D8),"",-(RawCurrent!D8/MIN(RawCurrent!D$7:D$28))) -> 0.037800021 | E8: =IF(ISBLANK(RawCurrent!E8),"",-(RawCurrent!E8/MIN(RawCurrent!E$7:E$28))) -> -0.017521348 | F8: =IF(ISBLANK(RawCurrent!F8),"",-(RawCurrent!F8/MIN(RawCurrent!F$7:F$28))) -> 0.045177226 | G8: =IF(ISBLANK(RawCurrent!G8),"",-(RawCurrent!G8/MIN(RawCurrent!G$7:G$28))) -> 0.0069468973 | H8: =IF(ISBLANK(RawCurrent!H8),"",-(RawCurrent!H8/MIN(RawCurrent!H$7:H$28))) -> -0.010049072 | I8: =IF(ISBLANK(RawCurrent!I8),"",-(RawCurrent!I8/MIN(RawCurrent!I$7:I$28))) -> 0.022538373 | ... CD8: =IF(ISBLANK(RawCurrent!CD8),"",-(RawCurrent!CD8/MIN(RawCurrent!CD$7:CD$28))) -> 0.0039656124
A9: =A8+10 -> -60 | B9: =IF(ISBLANK(RawCurrent!B9),"",-(RawCurrent!B9/MIN(RawCurrent!B$7:B$28))) -> -0.022972838 | C9: =IF(ISBLANK(RawCurrent!C9),"",-(RawCurrent!C9/MIN(RawCurrent!C$7:C$28))) -> 0.045688693 | D9: =IF(ISBLANK(RawCurrent!D9),"",-(RawCurrent!D9/MIN(RawCurrent!D$7:D$28))) -> 0.045111469 | E9: =IF(ISBLANK(RawCurrent!E9),"",-(RawCurrent!E9/MIN(RawCurrent!E$7:E$28))) -> -0.013236277 | F9: =IF(ISBLANK(RawCurrent!F9),"",-(RawCurrent!F9/MIN(RawCurrent!F$7:F$28))) -> -0.043721367 | G9: =IF(ISBLANK(RawCurrent!G9),"",-(RawCurrent!G9/MIN(RawCurrent!G$7:G$28))) -> 0.010059949 | H9: =IF(ISBLANK(RawCurrent!H9),"",-(RawCurrent!H9/MIN(RawCurrent!H$7:H$28))) -> 0.0092871194 | I9: =IF(ISBLANK(RawCurrent!I9),"",-(RawCurrent!I9/MIN(RawCurrent!I$7:I$28))) -> 0.028551896 | ... CD9: =IF(ISBLANK(RawCurrent!CD9),"",-(RawCurrent!CD9/MIN(RawCurrent!CD$7:CD$28))) -> 0.04792383
A10: =A9+10 -> -50 | B10: =IF(ISBLANK(RawCurrent!B10),"",-(RawCurrent!B10/MIN(RawCurrent!B$7:B$28))) -> -0.031979033 | C10: =IF(ISBLANK(RawCurrent!C10),"",-(RawCurrent!C10/MIN(RawCurrent!C$7:C$28))) -> -0.054400475 | D10: =IF(ISBLANK(RawCurrent!D10),"",-(RawCurrent!D10/MIN(RawCurrent!D$7:D$28))) -> 0.04594552 | E10: =IF(ISBLANK(RawCurrent!E10),"",-(RawCurrent!E10/MIN(RawCurrent!E$7:E$28))) -> 0.018423017 | F10: =IF(ISBLANK(RawCurrent!F10),"",-(RawCurrent!F10/MIN(RawCurrent!F$7:F$28))) -> 0.039649626 | G10: =IF(ISBLANK(RawCurrent!G10),"",-(RawCurrent!G10/MIN(RawCurrent!G$7:G$28))) -> 0.010068902 | H10: =IF(ISBLANK(RawCurrent!H10),"",-(RawCurrent!H10/MIN(RawCurrent!H$7:H$28))) -> -0.010312495 | I10: =IF(ISBLANK(RawCurrent!I10),"",-(RawCurrent!I10/MIN(RawCurrent!I$7:I$28))) -> 0.035365675 | ... CD10: =IF(ISBLANK(RawCurrent!CD10),"",-(RawCurrent!CD10/MIN(RawCurrent!CD$7:CD$28))) -> 0.034863398
A11: =A10+10 -> -40 | B11: =IF(ISBLANK(RawCurrent!B11),"",-(RawCurrent!B11/MIN(RawCurrent!B$7:B$28))) -> -0.032947829 | C11: =IF(ISBLANK(RawCurrent!C11),"",-(RawCurrent!C11/MIN(RawCurrent!C$7:C$28))) -> -0.067771389 | D11: =IF(ISBLANK(RawCurrent!D11),"",-(RawCurrent!D11/MIN(RawCurrent!D$7:D$28))) -> 0.052465443 | E11: =IF(ISBLANK(RawCurrent!E11),"",-(RawCurrent!E11/MIN(RawCurrent!E$7:E$28))) -> 0.021939159 | F11: =IF(ISBLANK(RawCurrent!F11),"",-(RawCurrent!F11/MIN(RawCurrent!F$7:F$28))) -> -0.038881525 | G11: =IF(ISBLANK(RawCurrent!G11),"",-(RawCurrent!G11/MIN(RawCurrent!G$7:G$28))) -> -0.020392541 | H11: =IF(ISBLANK(RawCurrent!H11),"",-(RawCurrent!H11/MIN(RawCurrent!H$7:H$28))) -> -0.0085164908 | I11: =IF(ISBLANK(RawCurrent!I11),"",-(RawCurrent!I11/MIN(RawCurrent!I$7:I$28))) -> 0.037573667 | ... CD11: =IF(ISBLANK(RawCurrent!CD11),"",-(RawCurrent!CD11/MIN(RawCurrent!CD$7:CD$28))) -> 0.056792532
A12: =A11+10 -> -30 | B12: =IF(ISBLANK(RawCurrent!B12),"",-(RawCurrent!B12/MIN(RawCurrent!B$7:B$28))) -> -0.079330805 | C12: =IF(ISBLANK(RawCurrent!C12),"",-(RawCurrent!C12/MIN(RawCurrent!C$7:C$28))) -> -0.3025628 | D12: =IF(ISBLANK(RawCurrent!D12),"",-(RawCurrent!D12/MIN(RawCurrent!D$7:D$28))) -> 0.039789961 | E12: =IF(ISBLANK(RawCurrent!E12),"",-(RawCurrent!E12/MIN(RawCurrent!E$7:E$28))) -> -0.060939941 | F12: =IF(ISBLANK(RawCurrent!F12),"",-(RawCurrent!F12/MIN(RawCurrent!F$7:F$28))) -> -0.082291322 | G12: =IF(ISBLANK(RawCurrent!G12),"",-(RawCurrent!G12/MIN(RawCurrent!G$7:G$28))) -> -0.23802254 | H12: =IF(ISBLANK(RawCurrent!H12),"",-(RawCurrent!H12/MIN(RawCurrent!H$7:H$28))) -> -0.028422207 | I12: =IF(ISBLANK(RawCurrent!I12),"",-(RawCurrent!I12/MIN(RawCurrent!I$7:I$28))) -> -0.23291629 | ... CD12: =IF(ISBLANK(RawCurrent!CD12),"",-(RawCurrent!CD12/MIN(RawCurrent!CD$7:CD$28))) -> -0.097300945
A13: =A12+10 -> -20 | B13: =IF(ISBLANK(RawCurrent!B13),"",-(RawCurrent!B13/MIN(RawCurrent!B$7:B$28))) -> -0.33802113 | C13: =IF(ISBLANK(RawCurrent!C13),"",-(RawCurrent!C13/MIN(RawCurrent!C$7:C$28))) -> -0.73789054 | D13: =IF(ISBLANK(RawCurrent!D13),"",-(RawCurrent!D13/MIN(RawCurrent!D$7:D$28))) -> -0.39589638 | E13: =IF(ISBLANK(RawCurrent!E13),"",-(RawCurrent!E13/MIN(RawCurrent!E$7:E$28))) -> -0.38051189 | F13: =IF(ISBLANK(RawCurrent!F13),"",-(RawCurrent!F13/MIN(RawCurrent!F$7:F$28))) -> -0.35216534 | G13: =IF(ISBLANK(RawCurrent!G13),"",-(RawCurrent!G13/MIN(RawCurrent!G$7:G$28))) -> -0.93307968 | H13: =IF(ISBLANK(RawCurrent!H13),"",-(RawCurrent!H13/MIN(RawCurrent!H$7:H$28))) -> -0.14231897 | I13: =IF(ISBLANK(RawCurrent!I13),"",-(RawCurrent!I13/MIN(RawCurrent!I$7:I$28))) -> -0.94391694 | ... CD13: =IF(ISBLANK(RawCurrent!CD13),"",-(RawCurrent!CD13/MIN(RawCurrent!CD$7:CD$28))) -> -0.26847354
A14: =A13+10 -> -10 | B14: =IF(ISBLANK(RawCurrent!B14),"",-(RawCurrent!B14/MIN(RawCurrent!B$7:B$28))) -> -0.72599301 | C14: =IF(ISBLANK(RawCurrent!C14),"",-(RawCurrent!C14/MIN(RawCurrent!C$7:C$28))) -> -0.93498753 | D14: =IF(ISBLANK(RawCurrent!D14),"",-(RawCurrent!D14/MIN(RawCurrent!D$7:D$28))) -> -0.92311044 | E14: =IF(ISBLANK(RawCurrent!E14),"",-(RawCurrent!E14/MIN(RawCurrent!E$7:E$28))) -> -0.83359814 | F14: =IF(ISBLANK(RawCurrent!F14),"",-(RawCurrent!F14/MIN(RawCurrent!F$7:F$28))) -> -0.8026739 | G14: =IF(ISBLANK(RawCurrent!G14),"",-(RawCurrent!G14/MIN(RawCurrent!G$7:G$28))) -> -1 | H14: =IF(ISBLANK(RawCurrent!H14),"",-(RawCurrent!H14/MIN(RawCurrent!H$7:H$28))) -> -0.54715962 | I14: =IF(ISBLANK(RawCurrent!I14),"",-(RawCurrent!I14/MIN(RawCurrent!I$7:I$28))) -> -1 | ... CD14: =IF(ISBLANK(RawCurrent!CD14),"",-(RawCurrent!CD14/MIN(RawCurrent!CD$7:CD$28))) -> -0.55302713
A15: =A14+10 -> 0 | B15: =IF(ISBLANK(RawCurrent!B15),"",-(RawCurrent!B15/MIN(RawCurrent!B$7:B$28))) -> -0.96441799 | C15: =IF(ISBLANK(RawCurrent!C15),"",-(RawCurrent!C15/MIN(RawCurrent!C$7:C$28))) -> -1 | D15: =IF(ISBLANK(RawCurrent!D15),"",-(RawCurrent!D15/MIN(RawCurrent!D$7:D$28))) -> -0.93661485 | E15: =IF(ISBLANK(RawCurrent!E15),"",-(RawCurrent!E15/MIN(RawCurrent!E$7:E$28))) -> -1 | F15: =IF(ISBLANK(RawCurrent!F15),"",-(RawCurrent!F15/MIN(RawCurrent!F$7:F$28))) -> -0.8956217 | G15: =IF(ISBLANK(RawCurrent!G15),"",-(RawCurrent!G15/MIN(RawCurrent!G$7:G$28))) -> -0.89753846 | H15: =IF(ISBLANK(RawCurrent!H15),"",-(RawCurrent!H15/MIN(RawCurrent!H$7:H$28))) -> -0.90283724 | I15: =IF(ISBLANK(RawCurrent!I15),"",-(RawCurrent!I15/MIN(RawCurrent!I$7:I$28))) -> -0.92212474 | ... CD15: =IF(ISBLANK(RawCurrent!CD15),"",-(RawCurrent!CD15/MIN(RawCurrent!CD$7:CD$28))) -> -0.84205182
A16: =A15+10 -> 10 | B16: =IF(ISBLANK(RawCurrent!B16),"",-(RawCurrent!B16/MIN(RawCurrent!B$7:B$28))) -> -1 | C16: =IF(ISBLANK(RawCurrent!C16),"",-(RawCurrent!C16/MIN(RawCurrent!C$7:C$28))) -> -0.91474034 | D16: =IF(ISBLANK(RawCurrent!D16),"",-(RawCurrent!D16/MIN(RawCurrent!D$7:D$28))) -> -1 | E16: =IF(ISBLANK(RawCurrent!E16),"",-(RawCurrent!E16/MIN(RawCurrent!E$7:E$28))) -> -0.93176498 | F16: =IF(ISBLANK(RawCurrent!F16),"",-(RawCurrent!F16/MIN(RawCurrent!F$7:F$28))) -> -1 | G16: =IF(ISBLANK(RawCurrent!G16),"",-(RawCurrent!G16/MIN(RawCurrent!G$7:G$28))) -> -0.81194213 | H16: =IF(ISBLANK(RawCurrent!H16),"",-(RawCurrent!H16/MIN(RawCurrent!H$7:H$28))) -> -1 | I16: =IF(ISBLANK(RawCurrent!I16),"",-(RawCurrent!I16/MIN(RawCurrent!I$7:I$28))) -> -0.83446703 | ... CD16: =IF(ISBLANK(RawCurrent!CD16),"",-(RawCurrent!CD16/MIN(RawCurrent!CD$7:CD$28))) -> -1
A17: =A16+10 -> 20 | B17: =IF(ISBLANK(RawCurrent!B17),"",-(RawCurrent!B17/MIN(RawCurrent!B$7:B$28))) -> -0.92989244 | C17: =IF(ISBLANK(RawCurrent!C17),"",-(RawCurrent!C17/MIN(RawCurrent!C$7:C$28))) -> -0.78773153 | D17: =IF(ISBLANK(RawCurrent!D17),"",-(RawCurrent!D17/MIN(RawCurrent!D$7:D$28))) -> -0.89342522 | E17: =IF(ISBLANK(RawCurrent!E17),"",-(RawCurrent!E17/MIN(RawCurrent!E$7:E$28))) -> -0.79821 | F17: =IF(ISBLANK(RawCurrent!F17),"",-(RawCurrent!F17/MIN(RawCurrent!F$7:F$28))) -> -0.9250131 | G17: =IF(ISBLANK(RawCurrent!G17),"",-(RawCurrent!G17/MIN(RawCurrent!G$7:G$28))) -> -0.68295245 | H17: =IF(ISBLANK(RawCurrent!H17),"",-(RawCurrent!H17/MIN(RawCurrent!H$7:H$28))) -> -0.96789002 | I17: =IF(ISBLANK(RawCurrent!I17),"",-(RawCurrent!I17/MIN(RawCurrent!I$7:I$28))) -> -0.70235557 | ... CD17: =IF(ISBLANK(RawCurrent!CD17),"",-(RawCurrent!CD17/MIN(RawCurrent!CD$7:CD$28))) -> -0.98818807
A18: =A17+10 -> 30 | B18: =IF(ISBLANK(RawCurrent!B18),"",-(RawCurrent!B18/MIN(RawCurrent!B$7:B$28))) -> -0.80192221 | C18: =IF(ISBLANK(RawCurrent!C18),"",-(RawCurrent!C18/MIN(RawCurrent!C$7:C$28))) -> -0.64318437 | D18: =IF(ISBLANK(RawCurrent!D18),"",-(RawCurrent!D18/MIN(RawCurrent!D$7:D$28))) -> -0.71771579 | E18: =IF(ISBLANK(RawCurrent!E18),"",-(RawCurrent!E18/MIN(RawCurrent!E$7:E$28))) -> -0.61708633 | F18: =IF(ISBLANK(RawCurrent!F18),"",-(RawCurrent!F18/MIN(RawCurrent!F$7:F$28))) -> -0.75565394 | G18: =IF(ISBLANK(RawCurrent!G18),"",-(RawCurrent!G18/MIN(RawCurrent!G$7:G$28))) -> -0.55146813 | H18: =IF(ISBLANK(RawCurrent!H18),"",-(RawCurrent!H18/MIN(RawCurrent!H$7:H$28))) -> -0.85400959 | I18: =IF(ISBLANK(RawCurrent!I18),"",-(RawCurrent!I18/MIN(RawCurrent!I$7:I$28))) -> -0.56086032 | ... CD18: =IF(ISBLANK(RawCurrent!CD18),"",-(RawCurrent!CD18/MIN(RawCurrent!CD$7:CD$28))) -> -0.7977435
A19: =A18+10 -> 40 | B19: =IF(ISBLANK(RawCurrent!B19),"",-(RawCurrent!B19/MIN(RawCurrent!B$7:B$28))) -> -0.6565583 | C19: =IF(ISBLANK(RawCurrent!C19),"",-(RawCurrent!C19/MIN(RawCurrent!C$7:C$28))) -> -0.47431939 | D19: =IF(ISBLANK(RawCurrent!D19),"",-(RawCurrent!D19/MIN(RawCurrent!D$7:D$28))) -> -0.50517786 | E19: =IF(ISBLANK(RawCurrent!E19),"",-(RawCurrent!E19/MIN(RawCurrent!E$7:E$28))) -> -0.42222852 | F19: =IF(ISBLANK(RawCurrent!F19),"",-(RawCurrent!F19/MIN(RawCurrent!F$7:F$28))) -> -0.53365251 | G19: =IF(ISBLANK(RawCurrent!G19),"",-(RawCurrent!G19/MIN(RawCurrent!G$7:G$28))) -> -0.43347315 | H19: =IF(ISBLANK(RawCurrent!H19),"",-(RawCurrent!H19/MIN(RawCurrent!H$7:H$28))) -> -0.70682135 | I19: =IF(ISBLANK(RawCurrent!I19),"",-(RawCurrent!I19/MIN(RawCurrent!I$7:I$28))) -> -0.42298274 | ... CD19: =IF(ISBLANK(RawCurrent!CD19),"",-(RawCurrent!CD19/MIN(RawCurrent!CD$7:CD$28))) -> -0.61185886
... A23: =A22+10 -> 80 | B23: =IF(ISBLANK(RawCurrent!B23),"",-(RawCurrent!B23/MIN(RawCurrent!B$7:B$28))) -> -0.079437751 | C23: =IF(ISBLANK(RawCurrent!C23),"",-(RawCurrent!C23/MIN(RawCurrent!C$7:C$28))) -> -0.070426275 | D23: =IF(ISBLANK(RawCurrent!D23),"",-(RawCurrent!D23/MIN(RawCurrent!D$7:D$28))) -> 0.13818946 | E23: =IF(ISBLANK(RawCurrent!E23),"",-(RawCurrent!E23/MIN(RawCurrent!E$7:E$28))) -> 0.16924493 | F23: =IF(ISBLANK(RawCurrent!F23),"",-(RawCurrent!F23/MIN(RawCurrent!F$7:F$28))) -> 0.40041072 | G23: =IF(ISBLANK(RawCurrent!G23),"",-(RawCurrent!G23/MIN(RawCurrent!G$7:G$28))) -> 0.071415314 | H23: =IF(ISBLANK(RawCurrent!H23),"",-(RawCurrent!H23/MIN(RawCurrent!H$7:H$28))) -> -0.10226881 | I23: =IF(ISBLANK(RawCurrent!I23),"",-(RawCurrent!I23/MIN(RawCurrent!I$7:I$28))) -> 0.038482672 | ... CD23: =IF(ISBLANK(RawCurrent!CD23),"",-(RawCurrent!CD23/MIN(RawCurrent!CD$7:CD$28))) -> 0.063327427
A24: =A23+10 -> 90 | B24: =IF(ISBLANK(RawCurrent!B24),"",-(RawCurrent!B24/MIN(RawCurrent!B$7:B$28))) -> 0.11925614 | C24: =IF(ISBLANK(RawCurrent!C24),"",-(RawCurrent!C24/MIN(RawCurrent!C$7:C$28))) -> 0.045216299 | K24: =IF(ISBLANK(RawCurrent!K24),"",-(RawCurrent!K24/MIN(RawCurrent!K$7:K$28))) -> 0.038817029 | M24: =IF(ISBLANK(RawCurrent!M24),"",-(RawCurrent!M24/MIN(RawCurrent!M$7:M$28))) -> 0.10496864 | AC24: =IF(ISBLANK(RawCurrent!AC24),"",-(RawCurrent!AC24/MIN(RawCurrent!AC$7:AC$28))) -> 0.25448934
A25: =A24+10 -> 100 | B25: =IF(ISBLANK(RawCurrent!B25),"",-(RawCurrent!B25/MIN(RawCurrent!B$7:B$28))) -> 0.21319678 | C25: =IF(ISBLANK(RawCurrent!C25),"",-(RawCurrent!C25/MIN(RawCurrent!C$7:C$28))) -> 0.088082524 | K25: =IF(ISBLANK(RawCurrent!K25),"",-(RawCurrent!K25/MIN(RawCurrent!K$7:K$28))) -> 0.10815944 | M25: =IF(ISBLANK(RawCurrent!M25),"",-(RawCurrent!M25/MIN(RawCurrent!M$7:M$28))) -> 0.19983203 | AC25: =IF(ISBLANK(RawCurrent!AC25),"",-(RawCurrent!AC25/MIN(RawCurrent!AC$7:AC$28))) -> 0.32309556
A26: =A25+10 -> 110 | B26: =IF(ISBLANK(RawCurrent!B26),"",-(RawCurrent!B26/MIN(RawCurrent!B$7:B$28))) -> 0.27655959 | C26: =IF(ISBLANK(RawCurrent!C26),"",-(RawCurrent!C26/MIN(RawCurrent!C$7:C$28))) -> 0.13338704 | K26: =IF(ISBLANK(RawCurrent!K26),"",-(RawCurrent!K26/MIN(RawCurrent!K$7:K$28))) -> 0.16582184 | M26: =IF(ISBLANK(RawCurrent!M26),"",-(RawCurrent!M26/MIN(RawCurrent!M$7:M$28))) -> 0.24445141 | AC26: =IF(ISBLANK(RawCurrent!AC26),"",-(RawCurrent!AC26/MIN(RawCurrent!AC$7:AC$28))) -> 0.38886914
A27: =A26+10 -> 120 | B27: =IF(ISBLANK(RawCurrent!B27),"",-(RawCurrent!B27/MIN(RawCurrent!B$7:B$28))) -> 0.31908031
A28: 130 | B28: =IF(ISBLANK(RawCurrent!B28),"",-(RawCurrent!B28/MIN(RawCurrent!B$7:B$28))) -> 0.34263537
A29: comment | F29: Great_cancellation | AY29: Great_cancellation | BS29: Great_cancellation

Sheet BLcorrectedCurrent
A1: Collector | B1: =RawCurrent!B1 -> REdC | C1: =RawCurrent!C1 -> REdC | D1: =RawCurrent!D1 -> REdC | E1: =RawCurrent!E1 -> REdC | F1: =RawCurrent!F1 -> REdC | G1: =RawCurrent!G1 -> REdC | H1: =RawCurrent!H1 -> REdC | I1: =RawCurrent!I1 -> REdC | ... CD1: =RawCurrent!CD1 -> REdC
A2: Filename | B2: =RawCurrent!B2 -> WT1_REdC_IV_18704034 | C2: =RawCurrent!C2 -> WT2_REdC_IV_1.26.2018 WT cell 5 IV' | D2: =RawCurrent!D2 -> WT3_REdC_IV_17728035 Final | E2: =RawCurrent!E2 -> WT4_REdC_IV_18705015 | F2: =RawCurrent!F2 -> WT5_REdC_IV_17728025 Final | G2: =RawCurrent!G2 -> WT6_REdC_IV_wt iv final | H2: =RawCurrent!H2 -> WT7_REdC_IV_1.26.2018 | I2: =RawCurrent!I2 -> WT8_REdC_IV | ... CD2: =RawCurrent!CD2 -> LVNV21_REdC_IV_17615002.abf;LVNV4_REdC_IV_17615007.abf
A3: Capacitance_Tau*I_0 (picoFarads) | B3: =RawCurrent!B3 -> 6.3918005 | C3: =RawCurrent!C3 -> 3.1770135 | D3: =RawCurrent!D3 -> 12.816808 | E3: =RawCurrent!E3 -> 6.4393644 | F3: =RawCurrent!F3 -> 4.1415548 | G3: =RawCurrent!G3 -> 6.7330415 | H3: =RawCurrent!H3 -> 6.1017498 | I3: =RawCurrent!I3 -> 5.2679979 | ... CD3: =RawCurrent!CD3 -> 1.5789424
A4: Genotype | B4: =RawCurrent!B4 -> WT | C4: =RawCurrent!C4 -> WT | D4: =RawCurrent!D4 -> WT | E4: =RawCurrent!E4 -> WT | F4: =RawCurrent!F4 -> WT | G4: =RawCurrent!G4 -> WT | H4: =RawCurrent!H4 -> WT | I4: =RawCurrent!I4 -> WT | ... CD4: =RawCurrent!CD4 -> LVNV
A5: CellID | B5: =RawCurrent!B5 -> WT1 | C5: =RawCurrent!C5 -> WT2 | D5: =RawCurrent!D5 -> WT3 | E5: =RawCurrent!E5 -> WT4 | F5: =RawCurrent!F5 -> WT5 | G5: =RawCurrent!G5 -> WT6 | H5: =RawCurrent!H5 -> WT7 | I5: =RawCurrent!I5 -> WT8 | ... CD5: =RawCurrent!CD5 -> LVNV21
A6: Em (mV) | CE6: Em | CF6: =CONCATENATE("WT_N_=_",COUNT(B7:AQ7,AS7:AU7)) -> WT_N_=_45 | CG6: =CONCATENATE("WTsem_N_=_",COUNT(B7:AQ7,AS7:AU7)) -> WTsem_N_=_45 | CH6: =CONCATENATE("EPN_N_=_",COUNT(AW7:BJ7)) -> EPN_N_=_12 | CI6: =CONCATENATE("EPN_N_=_",COUNT(AW7:BJ7)) -> EPN_N_=_12 | CJ6: =CONCATENATE("LVNV_N_=_",COUNT(BK7:CD7)) -> LVNV_N_=_20 | CK6: =CONCATENATE("LVNVsem_N_=_",COUNT(BK7:CD7)) -> LVNVsem_N_=_20 | CL6: =CONCATENATE("WT_N_=_",COUNT(H7:BB7)) -> WT_N_=_46 | CM6: =CONCATENATE("WTsem_N_=_",COUNT(H7:BB7)) -> WTsem_N_=_46 | CN6: =CONCATENATE("EPN_N_=_",COUNT(BC7:BP7)) -> EPN_N_=_13 | CO6: =CONCATENATE("EPN_N_=_",COUNT(BC7:BP7)) -> EPN_N_=_13 | CP6: =CONCATENATE("LVNV_N_=_",COUNT(BQ7:CJ7)) -> LVNV_N_=_20 | CQ6: =CONCATENATE("LVNVsem_N_=_",COUNT(BQ7:CJ7)) -> LVNVsem_N_=_20 | CR6: Wtmed | CS6: WTQ3 | CT6: WTQ1 | CU6: EPNmed | CV6: EPNQ3 | CW6: EPNQ1 | CX6: LVNVmed | CY6: LVNVQ3 | CZ6: LVNVQ1 | DA6: Wtmed | DB6: WTQ3 | DC6: WTQ1 | DD6: EPNmed | DE6: EPNQ3 | DF6: EPNQ1 | DG6: LVNVmed | DH6: LVNVQ3 | DI6: LVNVQ1
