Workbook

Sheet MetaData
A1: Collector | B1: Author who collected data
A2: Filename | B2: Filename from which these traces were extracted
A3: Capacitance (picoFarads) | B3: Capacitance of the cell collected either from capac.pro or from a part within the abovementioned filename
A4: Genotype | B4: SCN4A encoding NaV1.4 pore sequence; AA sequence reported here. NaV1.4+ (scored, WT, is TTX-sensitive) for translated SCN4A sequences reading 1276-MDIMYA-1281 in DIII and 1556-ICLFEITTSAGWDG-1569 in DIV. NaV1.4EPN (TTX-resistant, scored EPN) were mutagenized to reflect D1277E and A1281P in DIII and D1568N in DIV. NaV1.4LVNV (TTX-resistant, scored LVNV) were mutagenized to reflect I1556L, I1561V, D1568N, and G1569V.
A5: CellID | B5: A unique identifier for each cell from which recordings were obtained in the course of this research program. Each tab in this sheet shall bear this identifier to signify from which cell the enclosed current family were recorded. Simply, the CellID is composed of the Genotype (as written above) and the roughly chronological order in which the cell was recorded. There is an additional sheet in this document showing all the recordings which were obtained from each cell, ordered under its CellID.
A6: V_act | B6: This is the point at which half of the current has developed during serial step depolarizations of the test voltage.
A7: k_act | B7: This is the rate at which current develops with respect to test pulse potential.
A8: V_inact | B8: This is the point at which half of the current magnitude fails to develop during serial step depolarizations of the pre-pulse potential (conditioning voltage step).
A9: k_inact | B9: This is the rate at which current fails to develops with respect to pre-pulse potential.
A10: Imax | B10: This is the Maximum Current observed in the IV protocol (independent of the voltage at which it occurred). If only the fSSI was recorded, this is Imax from that file. This is only for normalizing purposes to verify the effects of clamping are not skewing results.
B11: These parameters were fit in OriginPro2020 using the Boltzmann equation: y = A2 + (A1-A2)/(1 + exp((x-x0)/dx)) where x0 is V1/2 and dx is k. The fitting routine is an orthogonal distance regression (pro)
A13: Notes | B13: In the accompanying OriginPro graphing file, there are several sheets. There are two sets of Steady State Activation (SSA) sheets, and consequently, two sets of kinetics (V1/2, k) here because two sheets of SSA conductance data were generated - one where current is normalized to driving force as calculated by the difference between test voltage and the predicted Nernst equilibrium potential (Eeq) and one where current is normalized to driving force as calculated by the difference between test voltage and the observed Reversal Potential (Erev). (Nernst potential calculation parameters include: R=8.314 J/mol*K, T = 22 + 273.15 K, z = +1, F = 96.485 J/mol*mV, Na_out = 145, Na_in = 10.) Despite any consequences to the distribution or clustering of these points, on the whole, I prefer using the Erev data, if for no other reason than I estimate it accounts for physical defects in the experiments, such as clamping and miniscule variations sodium ion gradients. Moreover, the delineation in grouping between fast Steady State Inactivation (fSSI) V1/2-k plots and SSA V1/2-k clusters is more pronounced using this more personalized calculation. This is ultimately only of aesthetic value provided the insignificance of the difference between genotypes.
A14: Window_Current | B14: Window_Current: The window currents were identified first by calculating the difference curve between the fSSI and SSA curves, assuming fSSI A1 = 1, A2 = 0, SSA A1 = 0, A2 = 1, and using the results of the fitting parameters to fill in the following equation =(1/(1+EXP((V-V_act)/k_act))+(1/(1+EXP((V-V_inact)/k_inact)))-1) over the range of -50 to -10. The values in of these difference curves were stripped of the '-' (minus) symbol to generate the absolute value of these curves. An index(match) style formula was used to find the voltage at which the difference curve reaches a minimum (i.e. where it would have crossed the x-axis if not for the effective absolute value approach) and then report the voltage at which the minimum occurs (i.e. the peak of the window current). An example formula might be: =INDEX($A$15:$A$4015,MATCH(MIN($B$15:$B$4015),$B$15:$B$4015,0),) where A:A is the voltage and B:B is the absolute value difference curve. The
A15: Window_Current_Report | B15: Window_Current_Report: This file is a subset of the data found in Window_Current, excluding cells which only produced one or the other fSSI or SSA thereby precluding peak_window_current analysis, and it only reports the voltage at which the peak window current occurs. The peak fraction available (I_max_window) was calculated by evaluating the SSA curve assuming A1 = 0, A2 = 1, V_1/2_act and k_act as found above it, where V = E(Iwp), the voltage at which the peak window current occurs. A sample calculation might be: =(-1/(1+EXP((B14-B6)/B7)))+1 where B14 is E(Iwp), B6 is V_act and B7 is k_act
A17: Sheets included in this file:
A18: k_V_actEeq_inact | B18: This sheet summarizes the kinetic parameters of steady-state activation and fast inactivation where activation was calculated relative to the calculated equilibrium potential for sodium, Eeq.
A19: k_V_actErev_inact | B19: This sheet summarizes the kinetic parameters of steady-state activation and fast inactivation where activation was calculated relative to the observed revesal potential, Erev.
A20: Window_current | B20: The curves generated here were used to find the peak of the window current down to 0.01mV.
A21: Window_Current_Report | B21: This sheet displays the individual values describing the window current parameters for each cell which produced both steady-state activation and fast inactivation curves.
A22: Window_Current_Central_Tendency | B22: This sheet summarizes the average voltge at which the peak window current is achieved as well as the fraction of current developed at the peak of the window.
A23: Avg_Window_Curves | B23: These are average and spread curves over the range where steady-state activation and fast inactivation overlap.
A24: k_act_V_act_by_GT_Eeq | B24: This sheet summarizes the fitted parameters of sigmoidal curve fitting in such a way that was amenable to statistical testing by R. The activation parameters were calculated relative to the calculated equilibrium potential for sodium, Eeq.
A25: k_act_V_act_by_GT_Erev | B25: This sheet summarizes the fitted parameters of sigmoidal curve fitting in such a way that was amenable to statistical testing by R. The activation parameters were calculated relative to the reversal potential, Erev.

Sheet k_V_actEeq_inact
A1: Collector | B1: REdC | C1: REdC | D1: REdC | E1: REdC | F1: REdC | G1: REdC | H1: REdC | I1: REdC | J1: REdC | K1: REdC | L1: REdC | M1: REdC | N1: REdC | O1: REdC | P1: REdC | Q1: REdC | R1: REdC | S1: REdC | T1: REdC | U1: REdC | V1: REdC | W1: REdC | X1: REdC | Y1: REdC | Z1: REdC | AA1: REdC | AB1: REdC | AC1: REdC | AD1: REdC | AE1: REdC | AF1: REdC | AG1: REdC | AH1: REdC | AI1: REdC | AJ1: REdC | AK1: REdC | AL1: REdC | AM1: REdC | AN1: REdC | AO1: REdC | AP1: REdC | AQ1: REdC | AR1: REdC | AS1: REdC | AT1: REdC | AU1: REdC | AV1: REdC | AW1: REdC | AX1: REdC | AY1: REdC | AZ1: REdC | BA1: REdC | BB1: REdC | BC1: REdC | BD1: REdC | BE1: REdC | BF1: REdC | BG1: REdC | BH1: REdC | BI1: REdC | BJ1: REdC | BK1: REdC | BL1: REdC | BM1: REdC | BN1: REdC | BO1: REdC | BP1: REdC | BQ1: REdC | BR1: REdC | BS1: REdC | BT1: REdC | BU1: REdC | BV1: REdC | BW1: REdC | BX1: REdC | BY1: REdC | BZ1: REdC | CA1: REdC | CB1: REdC | CC1: REdC | CD1: REdC | CE1: REdC | CF1: REdC | CG1: REdC | CH1: REdC | CI1: REdC | CJ1: REdC | CK1: REdC | CL1: REdC | CM1: REdC | CN1: REdC | CO1: REdC | CP1: REdC | CQ1: REdC | CR1: REdC
A2: Filename_act | B2: WT1_REdC_IV_18704034 | C2: WT2_REdC_IV_1.26.2018 WT cell 5 IV' | D2: WT3_REdC_IV_17728035 Final | E2: WT4_REdC_IV_18705015 | F2: WT5_REdC_IV_17728025 Final | G2: WT6_REdC_IV_wt iv final | H2: WT7_REdC_IV_1.26.2018 | I2: WT8_REdC_IV | J2: WT9_REdC_IV_17504013 Final | K2: WT10_REdC_IV_1.26.2018 WT cell 2 IV' -120 conditioning | L2: WT11_REdC_IV_17723017 | M2: WT12_REdC_IV_17721049 Final filtered | N2: WT13_REdC_IV_17723001 | O2: WT14_REdC_IV_19n15007 | P2: WT15_REdC_IV_19825000 | Q2: WT16_REdC_IV_18705033 | R2: WT17_REdC_IV_17721059 | S2: WT19_REdC_IV_19n23000 (-80:-10); WT19_REdC_IV_19n23009 (0:+80) | T2: WT20_REdC_IV_18115016 | U2: WT21_REdC_IV_19o30001 (-80:0),WT21_REdC_IV_19o30004(10:+80) | W2: WT23_REdC_1.19.2018 IV cell 2 WT leak | X2: WT24_REdC_IV_18705003(-80:10),WT24_REdC_IV_18705002(20:+80) | Y2: WT25_REdC_IV_18704045 | Z2: WT26_REdC_IV_17809014 | AA2: WT27_REdC_IV_1.23.2018 IV cell 1 WT | AB2: WT28_REdC_IV_1.23.2018 IV cell 1 WT | AC2: WT29_REdC_IV_18o19010 | AD2: WT30_REdC_IV_1.26.2018 WT cell 1 IV p8 20 sweeps | AE2: WT31_REdC_IV_18o07001 | AG2: WT33_REdC_IV_17728018 | AI2: WT38_REdC_IV_19o21015 | AJ2: WT39_REdC_IV_17429002 | AK2: WT40_REdC_IV_17810003 | AL2: WT43_REdC_IV_1.26.2018 WT cell 4 IV | AM2: WT44_REdC_IV_1.14.2018 IV cell 2 NaV1.4 wt | AN2: WT47_REdC_IV_19911011 | AO2: WT48_REdC_IV_19n06031 | AQ2: WT50_REdC_IV_19n06011 | AS2: WT53_REdC_IV_17504004 | AT2: WT54_REdC_IV_1.19.2018 IV cell 1 WT | AX2: WT63_REdC_IV_19n07011 | AY2: WT66_REdC_IV_18704009 | AZ2: WT69_REdC_IV_18o18036 | BA2: WT71_REdC_IV_17722009 | BB2: WT74_REdC_IV_0003.abf | BC2: WT75_REdC_IV_0015.abf | BD2: WT76_REdC_IV_0012.abf | BE2: EPN1_REdC_IV_17725093.abf | BF2: EPN2_REdC_IV_17725017.abf | BG2: EPN3_REdC_IV_18115045.abf | BH2: EPN4_REdC_IV_IV cell 2 NaV1.4 EPN.abf | BI2: EPN5_REdC_IV_17725043.abf | BJ2: EPN6_REdC_IV_1.14.2018 IV cell 1 NaV1.4 EPN.abf | BK2: EPN7_REdC_IV_17718015.abf | BL2: EPN9_REdC_IV_17725067.abf | BM2: EPN10_REdC_IV_2016_09_30_0029.abf | BN2: EPN11_REdC_IV_17725020.abf | BO2: EPN12_REdC_IV_1.19.2018 IV cell 1 EPN'.abf | BP2: EPN13_REdC_IV_2016_09_30_0015.abf | BQ2: EPN14_REdC_IV_17725071.abf | BT2: EPN18_REdC_IV_0012.abf | BW2: LVNV1_REdC_IV_17724088.abf | BX2: LVNV2_REdC_IV_17724059.abf;LVNV2_REdC_IV_17724048.abf;LVNV2_REdC_IV_17724046.abf | BY2: LVNV3_REdC_IV_17726022.abf | BZ2: LVNV4_REdC_IV_17429000.abf | CA2: LVNV5_REdC_IV_17724073.abf | CB2: LVNV6_REdC_IV_19915011.abf | CC2: LVNV7_REdC_IV_19d06007.abf | CD2: LVNV8_REdC_IV_17724003.abf;LVNV8_REdC_IV_17724001.abf | CE2: LVNV9_REdC_IV_17724034.abf | CF2: LVNV10_REdC_IV_17726060.abf;LVNV10_REdC_IV_17726061.abf | CH2: LVNV12_REdC_IV_19912002.abf | CJ2: LVNV14_REdC_IV_17726099.abf;LVNV14_REdC_IV_17726072.abf;LVNV14_REdC_IV_17726074.abf;LVNV14_REdC_IV_17726083.abf;LVNV14_REdC_IV_17726088.abf;LVNV14_REdC_IV_17726095.abf;LVNV14_REdC_IV_17726098.abf;LVNV14_REdC_IV_17726100.abf | CK2: LVNV15_REdC_IV_17724016.abf | CL2: LVNV16_REdC_IV_17726035.abf | CN2: LVNV18_REdC_IV_19911028.abf;LVNV18_REdC_IV_19911026.abf;LVNV18_REdC_IV_19911027.abf;LVNV18_REdC_IV_19911029.abf | CO2: LVNV19_REdC_IV_17714002.abf;LVNV19_REdC_IV_17714003.abf | CP2: LVNV20_REdC_IV_17726011.abf | CQ2: LVNV21_REdC_IV_17615002.abf;LVNV4_REdC_IV_17615007.abf
A3: Filename_inact | B3: WT1_REdC_fSSI_18704040 | D3: WT3_REdC_fSSI_17728036 | E3: WT4_REdC_fSSI_18705016 | F3: WT5_REdC_fSSI_17728026 | I3: WT8_REdC_fSSI_1.23.2018 fSSI cell 2 WT | J3: WT9_REdC_fSSI_17504014 | K3: WT10_REdC_fSSI_1.26.2018 WT cell 2 fSSI from -120 | L3: WT11_REdC_fSSI_17723028 | M3: WT12_REdC_fSSI_17721037 | N3: WT13_REdC_fSSI_17723002 | O3: WT14_REdC_fSSI_19n15001 | Q3: WT16_REdC_fSSI_18705034 | R3: WT17_REdC_fSSI_17721062 | T3: WT20_REdC_fSSI_18115015 | U3: WT21_REdC_fSSI_19o30003 | V3: WT22_REdC_fSSI_18o18024 | X3: WT24_REdC_fSSI_18705004 | Y3: WT25_REdC_fSSI_18704046 | Z3: WT26_REdC_fSSI_17809018 | AA3: WT27_REdC_fSSI_1.23.2018 fSSI cell 1 WT | AB3: WT28_REdC_fSSI_1.23.2018 fSSI cell 1 WT | AC3: WT29_REdC_fSSI_18o19011 | AD3: WT30_REdC_fSSI_1.26.2018 WT cell 1 Fssi | AE3: WT31_REdC_fSSI_18o07002 | AF3: WT32_REdC_fSSI_18704056 | AG3: WT33_REdC_fSSI_17728019 | AH3: WT36_REdC_fSSI_17809024 | AI3: WT38_REdC_fSSI_19o21003 | AJ3: WT39_REdC_fSSI_17429003 | AK3: WT40_REdC_fSSI_17810004 | AL3: WT43_REdC_fSSI_1.26.2018 WT cell 4 fSSI | AM3: WT44_REdC_fSSI_1.14.2018 fSSI cell 2 NaV1.4 wt | AN3: WT47_REdC_fSSI_19911006 | AO3: WT48_REdC_fSSI_19n06033 | AP3: WT49_REdC_fSSI_19830003 | AQ3: WT50_REdC_fSSI_19n06001 | AR3: WT52_REdC_fSSI_18704064 | AS3: WT53_REdC_fSSI_17504005 | AT3: WT54_REdC_fSSI_1.19.2018 fSSI cell 1 WT | AU3: WT57_REdC_fSSI_17721004 | AV3: WT59_REdC_fSSI_17728063 | AW3: WT60_REdC_fSSI_17804009- fSSI | AX3: WT63_REdC_fSSI_19n07001 | AY3: WT66_REdC_fSSI_18704010 | AZ3: WT69_REdC_fSSI_18o19004 | BB3: WT74_REdC_capac_0000.abf | BC3: WT75_REdC_capac_0000 | BD3: WT76_REdC_fSSI_0011.abf | BE3: EPN1_REdC_fSSI_17725094.abf | BF3: EPN2_REdC_fSSI_17725003.abf | BG3: EPN3_REdC_fSSI_18115041.abf | BH3: EPN4_REdC_fSSI_fSSI cell 2 NaV1.4 EPN.abf | BI3: EPN5_REdC_fSSI_17725042.abf | BJ3: EPN6_REdC_fSSI_1.14.2018 fSSI cell 1 NaV1.4 EPN.abf | BK3: EPN7_REdC_fSSI_17718002.abf | BL3: EPN9_REdC_fSSI_17725069.abf | BN3: EPN11_REdC_fSSI_17725022.abf | BO3: EPN12_REdC_fSSI_1.19.2018 fSSI cell 1 EPN.abf | BP3: EPN13_REdC_fSSI_2016_09_30_0008.abf | BQ3: EPN14_REdC_fSSI_17725073.abf | BR3: EPN15_REdC_fSSI_17725057.abf | BS3: EPN16_REdC_fSSI_2016_09_30_0003.abf | BT3: EPN18_REdC_fSSI_0008.abf | BU3: EPN19_REdC_fSSI_0002.abf | BV3: EPN20_REdC_fSSI_0002.abf | BW3: LVNV1_REdC_fSSI_17724087.abf | BX3: LVNV2_REdC_fSSI_17724049.abf | BY3: LVNV3_REdC_fSSI_17726025.abf | BZ3: LVNV4_REdC_fSSI_17429003.abf | CA3: LVNV5_REdC_fSSI_17724076.abf | CB3: LVNV6_REdC_fSSI_19915014.abf | CC3: LVNV7_REdC_fSSI_19d06005.abf | CD3: LVNV8_REdC_fSSI_17724004.abf | CE3: LVNV9_REdC_fSSI_17724035.abf | CF3: LVNV10_REdC_fSSI_17726051.abf | CG3: LVNV11_REdC_fSSI_17724070.abf | CH3: LVNV12_REdC_fSSI_19912003.abf | CI3: LVNV13_REdC_fSSI_19916006.abf | CJ3: LVNV14_REdC_fSSI_17726075.abf;LVNV14_REdC_fSSI_17726087.abf;LVNV14_REdC_fSSI_17726094.abf | CK3: LVNV15_REdC_fSSI_17724017.abf | CL3: LVNV16_REdC_fSSI_17726037.abf | CM3: LVNV17_REdC_fSSI_19912007.abf | CN3: LVNV18_REdC_fSSI_19911030.abf | CP3: LVNV20_REdC_fSSI_17726012.abf
A4: Genotype | B4: WT | C4: WT | D4: WT | E4: WT | F4: WT | G4: WT | H4: WT | I4: WT | J4: WT | K4: WT | L4: WT | M4: WT | N4: WT | O4: WT | P4: WT | Q4: WT | R4: WT | S4: WT | T4: WT | U4: WT | V4: WT | W4: WT | X4: WT | Y4: WT | Z4: WT | AA4: WT | AB4: WT | AC4: WT | AD4: WT | AE4: WT | AF4: WT | AG4: WT | AH4: WT | AI4: WT | AJ4: WT | AK4: WT | AL4: WT | AM4: WT | AN4: WT | AO4: WT | AP4: WT | AQ4: WT | AR4: WT | AS4: WT | AT4: WT | AU4: WT | AV4: WT | AW4: WT | AX4: WT | AY4: WT | AZ4: WT | BA4: WT | BB4: WT | BC4: WT | BD4: WT | BE4: EPN | BF4: EPN | BG4: EPN | BH4: EPN | BI4: EPN | BJ4: EPN | BK4: EPN | BL4: EPN | BM4: EPN | BN4: EPN | BO4: EPN | BP4: EPN | BQ4: EPN | BR4: EPN | BS4: EPN | BT4: EPN | BU4: EPN | BV4: EPN | BW4: LVNV | BX4: LVNV | BY4: LVNV | BZ4: LVNV | CA4: LVNV | CB4: LVNV | CC4: LVNV | CD4: LVNV | CE4: LVNV | CF4: LVNV | CG4: LVNV | CH4: LVNV | CI4: LVNV | CJ4: LVNV | CK4: LVNV | CL4: LVNV | CM4: LVNV | CN4: LVNV | CO4: LVNV | CP4: LVNV | CQ4: LVNV
A5: CellID | B5: WT1 | C5: WT2 | D5: WT3 | E5: WT4 | F5: WT5 | G5: WT6 | H5: WT7 | I5: WT8 | J5: WT9 | K5: WT10 | L5: WT11 | M5: WT12 | N5: WT13 | O5: WT14 | P5: WT15 | Q5: WT16 | R5: WT17 | S5: WT19 | T5: WT20 | U5: WT21 | V5: WT22 | W5: WT23 | X5: WT24 | Y5: WT25 | Z5: WT26 | AA5: WT27 | AB5: WT28 | AC5: WT29 | AD5: WT30 | AE5: WT31 | AF5: WT32 | AG5: WT33 | AH5: WT36 | AI5: WT38 | AJ5: WT39 | AK5: WT40 | AL5: WT43 | AM5: WT44 | AN5: WT47 | AO5: WT48 | AP5: WT49 | AQ5: WT50 | AR5: WT52 | AS5: WT53 | AT5: WT54 | AU5: WT57 | AV5: WT59 | AW5: WT60 | AX5: WT63 | AY5: WT66 | AZ5: WT69 | BA5: WT71 | BB5: WT74 | BC5: WT75 | BD5: WT76 | BE5: EPN1 | BF5: EPN2 | BG5: EPN3 | BH5: EPN4 | BI5: EPN5 | BJ5: EPN6 | BK5: EPN7 | BL5: EPN9 | BM5: EPN10 | BN5: EPN11 | BO5: EPN12 | BP5: EPN13 | BQ5: EPN14 | BR5: EPN15 | BS5: EPN16 | BT5: EPN18 | BU5: EPN19 | BV5: EPN20 | BW5: LVNV1 | BX5: LVNV2 | BY5: LVNV3 | BZ5: LVNV4 | CA5: LVNV5 | CB5: LVNV6 | CC5: LVNV7 | CD5: LVNV8 | CE5: LVNV9 | CF5: LVNV10 | CG5: LVNV11 | CH5: LVNV12 | CI5: LVNV13 | CJ5: LVNV14 | CK5: LVNV15 | CL5: LVNV16 | CM5: LVNV17 | CN5: LVNV18 | CO5: LVNV19 | CP5: LVNV20 | CQ5: LVNV21
A6: V_act_Eeq | B6: -6.9297309 | C6: -18.891771 | D6: -12.692811 | E6: -13.661476 | F6: -8.5089798 | G6: -9.103355 | H6: -2.4265809 | I6: -24.295774 | J6: -12.235128 | K6: -8.1864457 | L6: -9.3991345 | M6: -15.46441 | N6: -22.686222 | O6: -13.954144 | P6: 2.6277668 | Q6: -6.5622683 | R6: -3.8733569 | S6: -21.659692 | T6: -20.546923 | U6: -14.058876 | W6: -4.1308758 | X6: -7.9003059 | Y6: -10.027128 | Z6: -5.6909287 | AA6: -5.124207 | AB6: -6.1047899 | AC6: -11.705163 | AD6: -17.674021 | AE6: 7.810626 | AG6: 9.1807987 | AI6: -7.1020194 | AJ6: -9.7120051 | AK6: -4.2619948 | AL6: -9.2547685 | AM6: -6.2357998 | AN6: -13.145054 | AO6: -1.6449733 | AQ6: -5.8834355 | AS6: -4.9286799 | AT6: -12.357756 | AX6: -6.6329005 | AY6: -6.2528186 | AZ6: -9.7235364 | BA6: -8.6991965 | BB6: -2.1116508 | BC6: -6.8576552 | BD6: -4.2658232 | BE6: -2.4870313 | BF6: -12.258704 | BG6: -15.469886 | BH6: -2.0309976 | BI6: -1.705883 | BJ6: -7.491394 | BK6: -12.954143 | BL6: -6.5440604 | BM6: -6.501909 | BN6: -1.9071088 | BO6: 0.26193515 | BP6: -11.409339 | BQ6: -8.3311772 | BT6: -3.2633948 | BW6: -2.8752135 | BX6: -10.450392 | BY6: -5.3464752 | BZ6: -13.407666 | CA6: -5.7676012 | CB6: -9.0950274 | CC6: -15.495925 | CD6: -5.3424976 | CE6: -2.9993241 | CF6: -9.0104549 | CH6: 6.3238219 | CJ6: -7.3450594 | CK6: -8.8637759 | CL6: -8.0810043 | CN6: -6.3242865 | CO6: -11.629147 | CP6: 8.8030413 | CQ6: -2.9105846
A7: k_act_Eeq | B7: 9.3271968 | C7: 8.6400648 | D7: 7.1694941 | E7: 5.9033906 | F7: 9.4378581 | G7: 4.03006 | H7: 8.7608699 | I7: 3.8961604 | J7: 4.3920872 | K7: 8.1389197 | L7: 6.6382901 | M7: 5.566789 | N7: 3.3914092 | O7: 5.2912039 | P7: 4.5442902 | Q7: 7.6295855 | R7: 7.2180379 | S7: 8.3938354 | T7: 7.2956695 | U7: 5.2398516 | W7: 8.3972851 | X7: 5.0287666 | Y7: 6.8200505 | Z7: 6.6566142 | AA7: 8.9855457 | AB7: 8.5001047 | AC7: 6.5734399 | AD7: 7.2069818 | AE7: 6.9082769 | AG7: 11.992522 | AI7: 8.9178305 | AJ7: 8.3023557 | AK7: 7.9236634 | AL7: 6.9360648 | AM7: 8.0644532 | AN7: 7.4327884 | AO7: 6.1245309 | AQ7: 7.1448608 | AS7: 9.4562441 | AT7: 9.1584325 | AX7: 6.1412297 | AY7: 8.642452 | AZ7: 7.2435793 | BA7: 7.2391171 | BB7: 8.699712 | BC7: 6.8264662 | BD7: 7.8157199 | BE7: 8.7774231 | BF7: 9.0002487 | BG7: 8.3556406 | BH7: 9.560034 | BI7: 9.1478892 | BJ7: 10.141107 | BK7: 6.4681379 | BL7: 6.7304784 | BM7: 7.8297773 | BN7: 8.0103832 | BO7: 10.437601 | BP7: 5.6654973 | BQ7: 6.9092427 | BT7: 8.1845314 | BW7: 8.158705 | BX7: 7.6530359 | BY7: 8.6987218 | BZ7: 5.7875836 | CA7: 8.6925998 | CB7: 6.2855467 | CC7: 6.7875132 | CD7: 8.3649246 | CE7: 9.48588 | CF7: 7.9134623 | CH7: 8.6109768 | CJ7: 8.1515462 | CK7: 5.7832053 | CL7: 6.7847497 | CN7: 7.95857 | CO7: 9.5769032 | CP7: 13.450247 | CQ7: 9.5750317
A8: V_inact | B8: -61.810949 | D8: -55.892692 | E8: -56.233799 | F8: -56.913929 | I8: -65.497748 | J8: -70.671663 | K8: -64.871759 | L8: -62.242112 | M8: -58.611412 | N8: -58.859281 | O8: -52.754045 | Q8: -55.598744 | R8: -52.885693 | T8: -66.052187 | U8: -60.972634 | V8: -68.816124 | X8: -52.294763 | Y8: -63.342266 | Z8: -73.829378 | AA8: -80.63667 | AB8: -80.618315 | AC8: -54.180115 | AD8: -66.72168 | AE8: -42.800769 | AF8: -58.235578 | AG8: -61.018268 | AH8: -59.428457 | AI8: -52.511469 | AJ8: -65.294088 | AK8: -53.889759 | AL8: -74.8926 | AM8: -65.772452 | AN8: -59.592561 | AO8: -52.933589 | AP8: -56.784638 | AQ8: -56.858692 | AR8: -53.869519 | AS8: -59.078286 | AT8: -69.180191 | AU8: -56.90933 | AV8: -58.013564 | AW8: -57.497967 | AX8: -55.516487 | AY8: -51.44691 | AZ8: -63.622345 | BB8: -56.060698 | BC8: -57.283956 | BD8: -53.579678 | BE8: -66.612182 | BF8: -59.593911 | BG8: -71.529866 | BH8: -53.025927 | BI8: -54.535528 | BJ8: -68.194174 | BK8: -50.132349 | BL8: -57.387775 | BN8: -51.084895 | BO8: -76.922049 | BP8: -58.644583 | BQ8: -44.856575 | BR8: -60.33408 | BS8: -67.379783 | BT8: -53.43682 | BU8: -53.195452 | BV8: -46.94072 | BW8: -51.705697 | BX8: -57.383966 | BY8: -58.836399 | BZ8: -65.18164 | CA8: -68.748043 | CB8: -50.389338 | CC8: -62.798126 | CD8: -59.242373 | CE8: -59.971943 | CF8: -53.813671 | CG8: -59.095359 | CH8: -63.252571 | CI8: -56.76958 | CJ8: -54.301519 | CK8: -57.781133 | CL8: -57.851471 | CM8: -36.753182 | CN8: -46.169783 | CP8: -55.009096
A9: k_inact | B9: 10.553981 | D9: 5.7237352 | E9: 5.5268137 | F9: 5.2988996 | I9: 9.0417403 | J9: 6.5826891 | K9: 9.221333 | L9: 9.020873 | M9: 5.7388038 | N9: 7.2610634 | O9: 6.5956369 | Q9: 5.8477095 | R9: 8.2047188 | T9: 8.0482252 | U9: 6.44893 | V9: 8.646649 | X9: 10.321226 | Y9: 7.92437 | Z9: 9.4056536 | AA9: 8.3320957 | AB9: 8.322194 | AC9: 8.9825225 | AD9: 8.473987 | AE9: 10.73606 | AF9: 6.2821548 | AG9: 5.9863673 | AH9: 7.7716365 | AI9: 7.2448369 | AJ9: 6.7415608 | AK9: 5.0935077 | AL9: 6.8702441 | AM9: 6.8177301 | AN9: 11.356479 | AO9: 7.0486514 | AP9: 6.1079031 | AQ9: 7.4682192 | AR9: 7.4294046 | AS9: 10.173351 | AT9: 7.6020746 | AU9: 7.0065278 | AV9: 6.7126966 | AW9: 7.0449498 | AX9: 7.9577312 | AY9: 6.9521182 | AZ9: 7.2727332 | BB9: 10.492476 | BC9: 8.2446078 | BD9: 5.9636938 | BE9: 11.839401 | BF9: 6.2429619 | BG9: 8.9223955 | BH9: 8.4682083 | BI9: 7.288802 | BJ9: 2.03296 | BK9: 9.3232706 | BL9: 7.0621269 | BN9: 10.860821 | BO9: 3.2219705 | BP9: 12.108689 | BQ9: 14.501146 | BR9: 14.8107 | BS9: 9.3990088 | BT9: 4.9100407 | BU9: 7.4548546 | BV9: 7.2090172 | BW9: 4.9426887 | BX9: 8.0208437 | BY9: 6.1749463 | BZ9: 6.4428448 | CA9: 8.3297467 | CB9: 11.456721 | CC9: 6.5181594 | CD9: 7.350763 | CE9: 7.0302699 | CF9: 12.098751 | CG9: 16.619885 | CH9: 6.1243312 | CI9: 11.428902 | CJ9: 9.8665096 | CK9: 5.6477136 | CL9: 6.6263361 | CM9: 12.513331 | CN9: 6.1694331 | CP9: 7.8328246
A10: V_act_inact_ratio | B10: 0.1121117 | D10: 0.2270925 | E10: 0.24294066 | F10: 0.1495061 | I10: 0.3709406 | J10: 0.17312637 | K10: 0.12619429 | L10: 0.15100925 | M10: 0.2638464 | N10: 0.38543151 | O10: 0.26451326 | Q10: 0.11802908 | R10: 0.073240165 | T10: 0.31107104 | U10: 0.23057682 | X10: 0.1510726 | Y10: 0.15830075 | Z10: 0.07708217 | AA10: 0.063546858 | AB10: 0.075724603 | AC10: 0.21604168 | AD10: 0.26489173 | AE10: -0.18248798 | AG10: -0.15045984 | AI10: 0.13524701 | AJ10: 0.14874249 | AK10: 0.079087285 | AL10: 0.12357387 | AM10: 0.094808687 | AN10: 0.22058212 | AO10: 0.031076171 | AQ10: 0.10347469 | AS10: 0.083426251 | AT10: 0.17863142 | AX10: 0.11947623 | AY10: 0.12153925 | AZ10: 0.1528321 | BB10: 0.037667223 | BC10: 0.11971337 | BD10: 0.079616439 | BE10: 0.037335983 | BF10: 0.20570397 | BG10: 0.21627171 | BH10: 0.038301973 | BI10: 0.031280214 | BJ10: 0.10985387 | BK10: 0.25839888 | BL10: 0.11403231 | BN10: 0.037332147 | BO10: -0.0034052025 | BP10: 0.1945506 | BQ10: 0.18572923 | BT10: 0.061070153 | BW10: 0.055607287 | BX10: 0.18211345 | BY10: 0.090870196 | BZ10: 0.20569697 | CA10: 0.08389477 | CB10: 0.18049508 | CC10: 0.24675775 | CD10: 0.090180344 | CE10: 0.050012121 | CF10: 0.16743803 | CH10: -0.099977309 | CJ10: 0.13526435 | CK10: 0.1534026 | CL10: 0.13968537 | CN10: 0.13697891 | CP10: -0.16002883
A11: k_act_inact_ratio | B11: 0.88376099 | D11: 1.2525901 | E11: 1.0681363 | F11: 1.7810977 | I11: 0.43090824 | J11: 0.66721778 | K11: 0.88261856 | L11: 0.73588112 | M11: 0.97002603 | N11: 0.46706783 | O11: 0.8022279 | Q11: 1.3047135 | R11: 0.87974226 | T11: 0.90649421 | U11: 0.81251489 | X11: 0.48722569 | Y11: 0.86064261 | Z11: 0.70772479 | AA11: 1.0784257 | AB11: 1.0213779 | AC11: 0.73180333 | AD11: 0.85048299 | AE11: 0.64346482 | AG11: 2.0033054 | AI11: 1.2309222 | AJ11: 1.2315183 | AK11: 1.5556398 | AL11: 1.0095806 | AM11: 1.1828648 | AN11: 0.65449759 | AO11: 0.868894 | AQ11: 0.95670207 | AS11: 0.92951128 | AT11: 1.204728 | AX11: 0.77173124 | AY11: 1.2431394 | AZ11: 0.99599135 | BB11: 0.82913813 | BC11: 0.82799163 | BD11: 1.3105502 | BE11: 0.7413739 | BF11: 1.4416633 | BG11: 0.93647952 | BH11: 1.1289323 | BI11: 1.2550607 | BJ11: 4.9883456 | BK11: 0.69376275 | BL11: 0.95303843 | BN11: 0.73754856 | BO11: 3.2395084 | BP11: 0.46788694 | BQ11: 0.47646185 | BT11: 1.6668969 | BW11: 1.6506613 | BX11: 0.95414349 | BY11: 1.4087121 | BZ11: 0.8982963 | CA11: 1.0435611 | CB11: 0.54863398 | CC11: 1.0413236 | CD11: 1.1379669 | CE11: 1.349291 | CF11: 0.65407265 | CH11: 1.4060273 | CJ11: 0.82618337 | CK11: 1.0239905 | CL11: 1.0239067 | CN11: 1.2900002 | CP11: 1.7171643
A12: I_max_current_density | B12: -1083.4116 | C12: -316.72758 | D12: -228.12117 | E12: -595.72975 | F12: -822.36902 | G12: -505.84662 | H12: -327.53381 | I12: -366.84891 | J12: -969.31199 | K12: -508.80304 | L12: -105.93359 | M12: -433.45572 | N12: -180.17218 | O12: -206.23072 | P12: -268.44231 | Q12: -154.9775 | R12: -212.62512 | S12: -204.28477 | T12: -135.17437 | U12: -238.92971 | V12: -110.96289 | W12: -421.51422 | X12: -146.37058 | Y12: -223.98672 | Z12: -248.20879 | AA12: -347.04925 | AB12: -340.80464 | AC12: -57.275416 | AD12: -352.16318 | AE12: -92.013773 | AF12: -65.704294 | AG12: -261.54702 | AH12: -67.583905 | AI12: -159.14069 | AJ12: -138.88617 | AK12: -84.411819 | AL12: -106.85205 | AM12: -194.74397 | AN12: -77.728871 | AO12: -68.086536 | AP12: -30.698822 | AQ12: -112.27736 | AR12: -25.962288 | AS12: -23.244472 | AT12: -57.608602 | AU12: -21.605055 | AV12: -89.718528 | AW12: -18.195803 | AX12: -41.270992 | AY12: -33.220616 | AZ12: -27.241381 | BA12: -32.88586 | BB12: -36.182465 | BC12: -132.08839 | BD12: -24.547995 | BE12: -278.99706 | BF12: -317.17217 | BG12: -190.59813 | BH12: -353.37388 | BI12: -139.87579 | BJ12: -84.63518 | BK12: -62.340107 | BL12: -83.431577 | BM12: -94.104325 | BN12: -40.936519 | BO12: -128.11198 | BP12: -24.989662 | BQ12: -13.343705 | BR12: -71.789579 | BS12: -58.839443 | BT12: -22.181283 | BU12: -188.30988 | BV12: -66.498674 | BW12: -61.917711 | BX12: -86.945365 | BY12: -116.50274 | BZ12: -369.05681 | CA12: -118.67455 | CB12: -100.50035 | CC12: -126.76929 | CD12: -50.903207 | CE12: -80.608738 | CF12: -13.143409 | CG12: -55.402421 | CH12: -57.31447 | CI12: -24.311521 | CJ12: -42.659623 | CK12: -77.892754 | CL12: -24.996315 | CM12: -8.7681507 | CN12: -57.868413 | CO12: -24.270425 | CP12: -42.227423 | CQ12: -89.82481
A13: lnImax | B13: 6.9878703 | C13: 5.758042 | D13: 5.4298769 | E13: 6.3897871 | F13: 6.7121892 | G13: 6.2262335 | H13: 5.7915913 | I13: 5.9049501 | J13: 6.8765865 | K13: 6.232061 | L13: 4.6628124 | M13: 6.0717896 | N13: 5.193913 | O13: 5.3289955 | P13: 5.592636 | Q13: 5.04328 | R13: 5.3595306 | S13: 5.319515 | T13: 4.9065656 | U13: 5.4761694 | V13: 4.7091958 | W13: 6.0438535 | X13: 4.9861416 | Y13: 5.4115868 | Z13: 5.5142703 | AA13: 5.8494667 | AB13: 5.8313094 | AC13: 4.0478715 | AD13: 5.8640946 | AE13: 4.5219383 | AF13: 4.1851643 | AG13: 5.5666141 | AH13: 4.2133699 | AI13: 5.0697887 | AJ13: 4.9336547 | AK13: 4.4357074 | AL13: 4.6714452 | AM13: 5.2716857 | AN13: 4.3532268 | AO13: 4.2207795 | AP13: 3.4242243 | AQ13: 4.7209722 | AR13: 3.256645 | AS13: 3.1460673 | AT13: 4.0536719 | AU13: 3.0729273 | AV13: 4.4966773 | AW13: 2.901191 | AX13: 3.7201599 | AY13: 3.5031706 | AZ13: 3.3047372 | BA13: 3.4930428 | BB13: 3.5885746 | BC13: 4.8834713 | BD13: 3.2006302 | BE13: 5.6312012 | BF13: 5.7594447 | BG13: 5.2501672 | BH13: 5.8675267 | BI13: 4.9407548 | BJ13: 4.43835 | BK13: 4.132605 | BL13: 4.4240269 | BM13: 4.544404 | BN13: 3.7120225 | BO13: 4.8529048 | BP13: 3.2184622 | BQ13: 2.5910447 | BR13: 4.2737393 | BS13: 4.0748124 | BT13: 3.0992488 | BU13: 5.2380889 | BV13: 4.197182 | BW13: 4.1258063 | BX13: 4.4652799 | BY13: 4.7579148 | BZ13: 5.9109506 | CA13: 4.7763849 | CB13: 4.6101612 | CC13: 4.8423688 | CD13: 3.9299259 | CE13: 4.389607 | CF13: 2.5759204 | CG13: 4.0146233 | CH13: 4.0485531 | CI13: 3.1909504 | CJ13: 3.7532529 | CK13: 4.3553329 | CL13: 3.2187284 | CM13: 2.1711259 | CN13: 4.0581717 | CO13: 3.1892585 | CP13: 3.7430698 | CQ13: 4.4978612

Sheet k_V_actErev_inact
A1: Collector | B1: REdC | C1: REdC | D1: REdC | E1: REdC | F1: REdC | G1: REdC | H1: REdC | I1: REdC | J1: REdC | K1: REdC | L1: REdC | M1: REdC | N1: REdC | O1: REdC | P1: REdC | Q1: REdC | R1: REdC | S1: REdC | T1: REdC | U1: REdC | V1: REdC | W1: REdC | X1: REdC | Y1: REdC | Z1: REdC | AA1: REdC | AB1: REdC | AC1: REdC | AD1: REdC | AE1: REdC | AF1: REdC | AG1: REdC | AH1: REdC | AI1: REdC | AJ1: REdC | AK1: REdC | AL1: REdC | AM1: REdC | AN1: REdC | AO1: REdC | AP1: REdC | AQ1: REdC | AR1: REdC | AS1: REdC | AT1: REdC | AU1: REdC | AV1: REdC | AW1: REdC | AX1: REdC | AY1: REdC | AZ1: REdC | BA1: REdC | BB1: REdC | BC1: REdC | BD1: REdC | BE1: REdC | BF1: REdC | BG1: REdC | BH1: REdC | BI1: REdC | BJ1: REdC | BK1: REdC | BL1: REdC | BM1: REdC | BN1: REdC | BO1: REdC | BP1: REdC | BQ1: REdC | BR1: REdC | BS1: REdC | BT1: REdC | BU1: REdC | BV1: REdC | BW1: REdC | BX1: REdC | BY1: REdC | BZ1: REdC | CA1: REdC | CB1: REdC | CC1: REdC | CD1: REdC | CE1: REdC | CF1: REdC | CG1: REdC | CH1: REdC | CI1: REdC | CJ1: REdC | CK1: REdC | CL1: REdC | CM1: REdC | CN1: REdC | CO1: REdC | CP1: REdC | CQ1: REdC | CR1: REdC
A2: Filename_act | B2: WT1_REdC_IV_18704034 | C2: WT2_REdC_IV_1.26.2018 WT cell 5 IV' | D2: WT3_REdC_IV_17728035 Final | E2: WT4_REdC_IV_18705015 | F2: WT5_REdC_IV_17728025 Final | G2: WT6_REdC_IV_wt iv final | H2: WT7_REdC_IV_1.26.2018 | I2: WT8_REdC_IV | J2: WT9_REdC_IV_17504013 Final | K2: WT10_REdC_IV_1.26.2018 WT cell 2 IV' -120 conditioning | L2: WT11_REdC_IV_17723017 | M2: WT12_REdC_IV_17721049 Final filtered | N2: WT13_REdC_IV_17723001 | O2: WT14_REdC_IV_19n15007 | P2: WT15_REdC_IV_19825000 | Q2: WT16_REdC_IV_18705033 | R2: WT17_REdC_IV_17721059 | S2: WT19_REdC_IV_19n23000 (-80:-10); WT19_REdC_IV_19n23009 (0:+80) | T2: WT20_REdC_IV_18115016 | U2: WT21_REdC_IV_19o30001 (-80:0),WT21_REdC_IV_19o30004(10:+80) | W2: WT23_REdC_1.19.2018 IV cell 2 WT leak | X2: WT24_REdC_IV_18705003(-80:10),WT24_REdC_IV_18705002(20:+80) | Y2: WT25_REdC_IV_18704045 | Z2: WT26_REdC_IV_17809014 | AA2: WT27_REdC_IV_1.23.2018 IV cell 1 WT | AB2: WT28_REdC_IV_1.23.2018 IV cell 1 WT | AC2: WT29_REdC_IV_18o19010 | AD2: WT30_REdC_IV_1.26.2018 WT cell 1 IV p8 20 sweeps | AE2: WT31_REdC_IV_18o07001 | AG2: WT33_REdC_IV_17728018 | AI2: WT38_REdC_IV_19o21015 | AJ2: WT39_REdC_IV_17429002 | AK2: WT40_REdC_IV_17810003 | AL2: WT43_REdC_IV_1.26.2018 WT cell 4 IV | AM2: WT44_REdC_IV_1.14.2018 IV cell 2 NaV1.4 wt | AN2: WT47_REdC_IV_19911011 | AO2: WT48_REdC_IV_19n06031 | AQ2: WT50_REdC_IV_19n06011 | AS2: WT53_REdC_IV_17504004 | AT2: WT54_REdC_IV_1.19.2018 IV cell 1 WT | AX2: WT63_REdC_IV_19n07011 | AY2: WT66_REdC_IV_18704009 | AZ2: WT69_REdC_IV_18o18036 | BA2: WT71_REdC_IV_17722009 | BB2: WT74_REdC_IV_0003.abf | BC2: WT75_REdC_IV_0015.abf | BD2: WT76_REdC_IV_0012.abf | BE2: EPN1_REdC_IV_17725093.abf | BF2: EPN2_REdC_IV_17725017.abf | BG2: EPN3_REdC_IV_18115045.abf | BH2: EPN4_REdC_IV_IV cell 2 NaV1.4 EPN.abf | BI2: EPN5_REdC_IV_17725043.abf | BJ2: EPN6_REdC_IV_1.14.2018 IV cell 1 NaV1.4 EPN.abf | BK2: EPN7_REdC_IV_17718015.abf | BL2: EPN9_REdC_IV_17725067.abf | BM2: EPN10_REdC_IV_2016_09_30_0029.abf | BN2: EPN11_REdC_IV_17725020.abf | BO2: EPN12_REdC_IV_1.19.2018 IV cell 1 EPN'.abf | BP2: EPN13_REdC_IV_2016_09_30_0015.abf | BQ2: EPN14_REdC_IV_17725071.abf | BT2: EPN18_REdC_IV_0012.abf | BW2: LVNV1_REdC_IV_17724088.abf | BX2: LVNV2_REdC_IV_17724059.abf;LVNV2_REdC_IV_17724048.abf;LVNV2_REdC_IV_17724046.abf | BY2: LVNV3_REdC_IV_17726022.abf | BZ2: LVNV4_REdC_IV_17429000.abf | CA2: LVNV5_REdC_IV_17724073.abf | CB2: LVNV6_REdC_IV_19915011.abf | CC2: LVNV7_REdC_IV_19d06007.abf | CD2: LVNV8_REdC_IV_17724003.abf;LVNV8_REdC_IV_17724001.abf | CE2: LVNV9_REdC_IV_17724034.abf | CF2: LVNV10_REdC_IV_17726060.abf;LVNV10_REdC_IV_17726061.abf | CH2: LVNV12_REdC_IV_19912002.abf | CJ2: LVNV14_REdC_IV_17726099.abf;LVNV14_REdC_IV_17726072.abf;LVNV14_REdC_IV_17726074.abf;LVNV14_REdC_IV_17726083.abf;LVNV14_REdC_IV_17726088.abf;LVNV14_REdC_IV_17726095.abf;LVNV14_REdC_IV_17726098.abf;LVNV14_REdC_IV_17726100.abf | CK2: LVNV15_REdC_IV_17724016.abf | CL2: LVNV16_REdC_IV_17726035.abf | CN2: LVNV18_REdC_IV_19911028.abf;LVNV18_REdC_IV_19911026.abf;LVNV18_REdC_IV_19911027.abf;LVNV18_REdC_IV_19911029.abf | CO2: LVNV19_REdC_IV_17714002.abf;LVNV19_REdC_IV_17714003.abf | CP2: LVNV20_REdC_IV_17726011.abf | CQ2: LVNV21_REdC_IV_17615002.abf;LVNV4_REdC_IV_17615007.abf
A3: Filename_inact | B3: WT1_REdC_fSSI_18704040 | D3: WT3_REdC_fSSI_17728036 | E3: WT4_REdC_fSSI_18705016 | F3: WT5_REdC_fSSI_17728026 | I3: WT8_REdC_fSSI_1.23.2018 fSSI cell 2 WT | J3: WT9_REdC_fSSI_17504014 | K3: WT10_REdC_fSSI_1.26.2018 WT cell 2 fSSI from -120 | L3: WT11_REdC_fSSI_17723028 | M3: WT12_REdC_fSSI_17721037 | N3: WT13_REdC_fSSI_17723002 | O3: WT14_REdC_fSSI_19n15001 | Q3: WT16_REdC_fSSI_18705034 | R3: WT17_REdC_fSSI_17721062 | T3: WT20_REdC_fSSI_18115015 | U3: WT21_REdC_fSSI_19o30003 | V3: WT22_REdC_fSSI_18o18024 | X3: WT24_REdC_fSSI_18705004 | Y3: WT25_REdC_fSSI_18704046 | Z3: WT26_REdC_fSSI_17809018 | AA3: WT27_REdC_fSSI_1.23.2018 fSSI cell 1 WT | AB3: WT28_REdC_fSSI_1.23.2018 fSSI cell 1 WT | AC3: WT29_REdC_fSSI_18o19011 | AD3: WT30_REdC_fSSI_1.26.2018 WT cell 1 Fssi | AE3: WT31_REdC_fSSI_18o07002 | AF3: WT32_REdC_fSSI_18704056 | AG3: WT33_REdC_fSSI_17728019 | AH3: WT36_REdC_fSSI_17809024 | AI3: WT38_REdC_fSSI_19o21003 | AJ3: WT39_REdC_fSSI_17429003 | AK3: WT40_REdC_fSSI_17810004 | AL3: WT43_REdC_fSSI_1.26.2018 WT cell 4 fSSI | AM3: WT44_REdC_fSSI_1.14.2018 fSSI cell 2 NaV1.4 wt | AN3: WT47_REdC_fSSI_19911006 | AO3: WT48_REdC_fSSI_19n06033 | AP3: WT49_REdC_fSSI_19830003 | AQ3: WT50_REdC_fSSI_19n06001 | AR3: WT52_REdC_fSSI_18704064 | AS3: WT53_REdC_fSSI_17504005 | AT3: WT54_REdC_fSSI_1.19.2018 fSSI cell 1 WT | AU3: WT57_REdC_fSSI_17721004 | AV3: WT59_REdC_fSSI_17728063 | AW3: WT60_REdC_fSSI_17804009- fSSI | AX3: WT63_REdC_fSSI_19n07001 | AY3: WT66_REdC_fSSI_18704010 | AZ3: WT69_REdC_fSSI_18o19004 | BB3: WT74_REdC_capac_0000.abf | BC3: WT75_REdC_capac_0000 | BD3: WT76_REdC_fSSI_0011.abf | BE3: EPN1_REdC_fSSI_17725094.abf | BF3: EPN2_REdC_fSSI_17725003.abf | BG3: EPN3_REdC_fSSI_18115041.abf | BH3: EPN4_REdC_fSSI_fSSI cell 2 NaV1.4 EPN.abf | BI3: EPN5_REdC_fSSI_17725042.abf | BJ3: EPN6_REdC_fSSI_1.14.2018 fSSI cell 1 NaV1.4 EPN.abf | BK3: EPN7_REdC_fSSI_17718002.abf | BL3: EPN9_REdC_fSSI_17725069.abf | BN3: EPN11_REdC_fSSI_17725022.abf | BO3: EPN12_REdC_fSSI_1.19.2018 fSSI cell 1 EPN.abf | BP3: EPN13_REdC_fSSI_2016_09_30_0008.abf | BQ3: EPN14_REdC_fSSI_17725073.abf | BR3: EPN15_REdC_fSSI_17725057.abf | BS3: EPN16_REdC_fSSI_2016_09_30_0003.abf | BT3: EPN18_REdC_fSSI_0008.abf | BU3: EPN19_REdC_fSSI_0002.abf | BV3: EPN20_REdC_fSSI_0002.abf | BW3: LVNV1_REdC_fSSI_17724087.abf | BX3: LVNV2_REdC_fSSI_17724049.abf | BY3: LVNV3_REdC_fSSI_17726025.abf | BZ3: LVNV4_REdC_fSSI_17429003.abf | CA3: LVNV5_REdC_fSSI_17724076.abf | CB3: LVNV6_REdC_fSSI_19915014.abf | CC3: LVNV7_REdC_fSSI_19d06005.abf | CD3: LVNV8_REdC_fSSI_17724004.abf | CE3: LVNV9_REdC_fSSI_17724035.abf | CF3: LVNV10_REdC_fSSI_17726051.abf | CG3: LVNV11_REdC_fSSI_17724070.abf | CH3: LVNV12_REdC_fSSI_19912003.abf | CI3: LVNV13_REdC_fSSI_19916006.abf | CJ3: LVNV14_REdC_fSSI_17726075.abf;LVNV14_REdC_fSSI_17726087.abf;LVNV14_REdC_fSSI_17726094.abf | CK3: LVNV15_REdC_fSSI_17724017.abf | CL3: LVNV16_REdC_fSSI_17726037.abf | CM3: LVNV17_REdC_fSSI_19912007.abf | CN3: LVNV18_REdC_fSSI_19911030.abf | CP3: LVNV20_REdC_fSSI_17726012.abf
A4: Genotype | B4: WT | C4: WT | D4: WT | E4: WT | F4: WT | G4: WT | H4: WT | I4: WT | J4: WT | K4: WT | L4: WT | M4: WT | N4: WT | O4: WT | P4: WT | Q4: WT | R4: WT | S4: WT | T4: WT | U4: WT | V4: WT | W4: WT | X4: WT | Y4: WT | Z4: WT | AA4: WT | AB4: WT | AC4: WT | AD4: WT | AE4: WT | AF4: WT | AG4: WT | AH4: WT | AI4: WT | AJ4: WT | AK4: WT | AL4: WT | AM4: WT | AN4: WT | AO4: WT | AP4: WT | AQ4: WT | AR4: WT | AS4: WT | AT4: WT | AU4: WT | AV4: WT | AW4: WT | AX4: WT | AY4: WT | AZ4: WT | BA4: WT | BB4: WT | BC4: WT | BD4: WT | BE4: EPN | BF4: EPN | BG4: EPN | BH4: EPN | BI4: EPN | BJ4: EPN | BK4: EPN | BL4: EPN | BM4: EPN | BN4: EPN | BO4: EPN | BP4: EPN | BQ4: EPN | BR4: EPN | BS4: EPN | BT4: EPN | BU4: EPN | BV4: EPN | BW4: LVNV | BX4: LVNV | BY4: LVNV | BZ4: LVNV | CA4: LVNV | CB4: LVNV | CC4: LVNV | CD4: LVNV | CE4: LVNV | CF4: LVNV | CG4: LVNV | CH4: LVNV | CI4: LVNV | CJ4: LVNV | CK4: LVNV | CL4: LVNV | CM4: LVNV | CN4: LVNV | CO4: LVNV | CP4: LVNV | CQ4: LVNV
A5: CellID | B5: WT1 | C5: WT2 | D5: WT3 | E5: WT4 | F5: WT5 | G5: WT6 | H5: WT7 | I5: WT8 | J5: WT9 | K5: WT10 | L5: WT11 | M5: WT12 | N5: WT13 | O5: WT14 | P5: WT15 | Q5: WT16 | R5: WT17 | S5: WT19 | T5: WT20 | U5: WT21 | V5: WT22 | W5: WT23 | X5: WT24 | Y5: WT25 | Z5: WT26 | AA5: WT27 | AB5: WT28 | AC5: WT29 | AD5: WT30 | AE5: WT31 | AF5: WT32 | AG5: WT33 | AH5: WT36 | AI5: WT38 | AJ5: WT39 | AK5: WT40 | AL5: WT43 | AM5: WT44 | AN5: WT47 | AO5: WT48 | AP5: WT49 | AQ5: WT50 | AR5: WT52 | AS5: WT53 | AT5: WT54 | AU5: WT57 | AV5: WT59 | AW5: WT60 | AX5: WT63 | AY5: WT66 | AZ5: WT69 | BA5: WT71 | BB5: WT74 | BC5: WT75 | BD5: WT76 | BE5: EPN1 | BF5: EPN2 | BG5: EPN3 | BH5: EPN4 | BI5: EPN5 | BJ5: EPN6 | BK5: EPN7 | BL5: EPN9 | BM5: EPN10 | BN5: EPN11 | BO5: EPN12 | BP5: EPN13 | BQ5: EPN14 | BR5: EPN15 | BS5: EPN16 | BT5: EPN18 | BU5: EPN19 | BV5: EPN20 | BW5: LVNV1 | BX5: LVNV2 | BY5: LVNV3 | BZ5: LVNV4 | CA5: LVNV5 | CB5: LVNV6 | CC5: LVNV7 | CD5: LVNV8 | CE5: LVNV9 | CF5: LVNV10 | CG5: LVNV11 | CH5: LVNV12 | CI5: LVNV13 | CJ5: LVNV14 | CK5: LVNV15 | CL5: LVNV16 | CM5: LVNV17 | CN5: LVNV18 | CO5: LVNV19 | CP5: LVNV20 | CQ5: LVNV21
A6: V_act_Erev | B6: -11.893189 | C6: -21.307124 | D6: -13.113383 | E6: -14.492698 | F6: -7.2988876 | G6: -9.103355 | H6: 5.6677789 | I6: -24.776988 | J6: -12.295355 | K6: -10.347405 | L6: -9.4066368 | M6: -16.731332 | N6: -22.439747 | O6: -13.95828 | P6: 2.5330249 | Q6: -8.1928835 | R6: -4.2792807 | S6: -21.43483 | T6: -10.667967 | U6: -14.49881 | W6: -4.8513771 | X6: -6.2567251 | Y6: -10.897064 | Z6: -6.1586836 | AA6: -5.5955477 | AB6: -6.072556 | AC6: -12.354167 | AD6: -13.411517 | AE6: 6.2185301 | AG6: 7.2454954 | AI6: -8.3078498 | AJ6: -11.596596 | AK6: -4.7036246 | AL6: -8.9175 | AM6: -7.8455289 | AN6: -13.523399 | AO6: -3.76205 | AQ6: -7.2084227 | AT6: -12.5865 | AX6: -5.310725 | AY6: -4.36795 | AZ6: -11.971919 | BA6: -10.362859 | BB6: -4.105028 | BC6: -7.4050458 | BD6: -2.2405886 | BE6: -3.224202 | BF6: -12.063375 | BG6: -17.510011 | BH6: -5.8318676 | BI6: -4.4054419 | BJ6: -6.9000827 | BK6: -11.89204 | BL6: -5.2631182 | BM6: -8.3530448 | BN6: -1.6437874 | BO6: -5.2489907 | BP6: -12.191047 | BQ6: -13.376909 | BT6: -0.76719344 | BW6: -3.7037154 | BX6: -13.950467 | BY6: -6.7575734 | BZ6: -17.517262 | CA6: -3.1999735 | CB6: -8.9048019 | CC6: -15.142334 | CD6: -6.3117674 | CE6: -6.1017701 | CF6: -10.86271 | CH6: 4.0810617 | CJ6: -8.3455382 | CK6: -8.7834957 | CL6: -6.0719264 | CN6: -3.8530842 | CO6: -16.88731 | CP6: -5.256282 | CQ6: -7.0976532
A7: k_act_Erev | B7: 6.4829144 | C7: 6.6801024 | D7: 7.0134718 | E7: 5.2872971 | F7: 9.7912631 | G7: 4.03006 | H7: 2.1217426 | I7: 3.6054903 | J7: 4.2309302 | K7: 4.4851231 | L7: 6.6388003 | M7: 4.7195387 | N7: 3.8166171 | O7: 5.206627 | P7: 4.3887196 | Q7: 6.5853558 | R7: 6.6405857 | S7: 8.3736724 | T7: 9.6830389 | U7: 4.7881119 | W7: 8.0416174 | X7: 5.9690346 | Y7: 6.3728018 | Z7: 6.4196143 | AA7: 8.9916863 | AB7: 8.0157498 | AC7: 5.8942386 | AD7: 2.7655786 | AE7: 6.4011585 | AG7: 9.4502473 | AI7: 7.8713322 | AJ7: 7.2134055 | AK7: 7.5708541 | AL7: 6.7669796 | AM7: 8.1187186 | AN7: 6.5533518 | AO7: 5.4196226 | AQ7: 6.324599 | AT7: 9.6662384 | AX7: 6.9319466 | AY7: 14.288264 | AZ7: 8.8055881 | BA7: 7.6621197 | BB7: 9.4084188 | BC7: 6.6223184 | BD7: 8.5304158 | BE7: 8.5439597 | BF7: 3.3832945 | BG7: 6.9329192 | BH7: 7.2694205 | BI7: 7.6395251 | BJ7: 14.27214 | BK7: 6.6809011 | BL7: 7.0121505 | BM7: 7.2698774 | BN7: 7.9633693 | BO7: 8.1680531 | BP7: 5.2496131 | BQ7: 3.7302858 | BT7: 10.506408 | BW7: 7.4671515 | BX7: 7.4181175 | BY7: 8.2821358 | BZ7: 4.0079812 | CA7: 9.8466314 | CB7: 5.5988693 | CC7: 7.4022557 | CD7: 7.4941831 | CE7: 10.492991 | CF7: 7.8308324 | CH7: 8.8195383 | CJ7: 8.4795329 | CK7: 5.7751146 | CL7: 7.2650782 | CN7: 10.846425 | CO7: 6.9302935 | CP7: 14.502148 | CQ7: 10.016532
A8: V_inact | B8: -61.810949 | D8: -55.892692 | E8: -56.233799 | F8: -56.913929 | I8: -65.497748 | J8: -70.671663 | K8: -64.871759 | L8: -62.242112 | M8: -58.611412 | N8: -58.859281 | O8: -52.754045 | Q8: -55.598744 | R8: -52.885693 | T8: -66.052187 | U8: -60.972634 | V8: -68.816124 | X8: -52.294763 | Y8: -63.342266 | Z8: -73.829378 | AA8: -80.63667 | AB8: -80.618315 | AC8: -54.180115 | AD8: -66.72168 | AE8: -42.800769 | AF8: -58.235578 | AG8: -61.018268 | AH8: -59.428457 | AI8: -52.511469 | AJ8: -65.294088 | AK8: -53.889759 | AL8: -74.8926 | AM8: -65.772452 | AN8: -59.592561 | AO8: -52.933589 | AP8: -56.784638 | AQ8: -56.858692 | AR8: -53.869519 | AS8: -59.078286 | AT8: -69.180191 | AU8: -56.90933 | AV8: -58.013564 | AW8: -57.497967 | AX8: -55.516487 | AY8: -51.44691 | AZ8: -63.622345 | BB8: -56.060698 | BC8: -57.283956 | BD8: -53.579678 | BE8: -66.612182 | BF8: -59.593911 | BG8: -71.529866 | BH8: -53.025927 | BI8: -54.535528 | BJ8: -68.194174 | BK8: -50.132349 | BL8: -57.387775 | BN8: -51.084895 | BO8: -76.922049 | BP8: -58.644583 | BQ8: -44.856575 | BR8: -60.33408 | BS8: -67.379783 | BT8: -53.43682 | BU8: -53.195452 | BV8: -46.94072 | BW8: -51.705697 | BX8: -57.383966 | BY8: -58.836399 | BZ8: -65.18164 | CA8: -68.748043 | CB8: -50.389338 | CC8: -62.798126 | CD8: -59.242373 | CE8: -59.971943 | CF8: -53.813671 | CG8: -59.095359 | CH8: -63.252571 | CI8: -56.76958 | CJ8: -54.301519 | CK8: -57.781133 | CL8: -57.851471 | CM8: -36.753182 | CN8: -46.169783 | CP8: -55.009096
A9: k_inact | B9: 10.553981 | D9: 5.7237352 | E9: 5.5268137 | F9: 5.2988996 | I9: 9.0417403 | J9: 6.5826891 | K9: 9.221333 | L9: 9.020873 | M9: 5.7388038 | N9: 7.2610634 | O9: 6.5956369 | Q9: 5.8477095 | R9: 8.2047188 | T9: 8.0482252 | U9: 6.44893 | V9: 8.646649 | X9: 10.321226 | Y9: 7.92437 | Z9: 9.4056536 | AA9: 8.3320957 | AB9: 8.322194 | AC9: 8.9825225 | AD9: 8.473987 | AE9: 10.73606 | AF9: 6.2821548 | AG9: 5.9863673 | AH9: 7.7716365 | AI9: 7.2448369 | AJ9: 6.7415608 | AK9: 5.0935077 | AL9: 6.8702441 | AM9: 6.8177301 | AN9: 11.356479 | AO9: 7.0486514 | AP9: 6.1079031 | AQ9: 7.4682192 | AR9: 7.4294046 | AS9: 10.173351 | AT9: 7.6020746 | AU9: 7.0065278 | AV9: 6.7126966 | AW9: 7.0449498 | AX9: 7.9577312 | AY9: 6.9521182 | AZ9: 7.2727332 | BB9: 10.492476 | BC9: 8.2446078 | BD9: 5.9636938 | BE9: 11.839401 | BF9: 6.2429619 | BG9: 8.9223955 | BH9: 8.4682083 | BI9: 7.288802 | BJ9: 2.03296 | BK9: 9.3232706 | BL9: 7.0621269 | BN9: 10.860821 | BO9: 3.2219705 | BP9: 12.108689 | BQ9: 14.501146 | BR9: 14.8107 | BS9: 9.3990088 | BT9: 4.9100407 | BU9: 7.4548546 | BV9: 7.2090172 | BW9: 4.9426887 | BX9: 8.0208437 | BY9: 6.1749463 | BZ9: 6.4428448 | CA9: 8.3297467 | CB9: 11.456721 | CC9: 6.5181594 | CD9: 7.350763 | CE9: 7.0302699 | CF9: 12.098751 | CG9: 16.619885 | CH9: 6.1243312 | CI9: 11.428902 | CJ9: 9.8665096 | CK9: 5.6477136 | CL9: 6.6263361 | CM9: 12.513331 | CN9: 6.1694331 | CP9: 7.8328246
A10: V_act_inact_ratio | B10: 0.1121117 | D10: 0.2270925 | E10: 0.24294066 | F10: 0.1495061 | I10: 0.3709406 | J10: 0.17312637 | K10: 0.12619429 | L10: 0.15100925 | M10: 0.2638464 | N10: 0.38543151 | O10: 0.26451326 | Q10: 0.11802908 | R10: 0.073240165 | T10: 0.31107104 | U10: 0.23057682 | X10: 0.1510726 | Y10: 0.15830075 | Z10: 0.07708217 | AA10: 0.063546858 | AB10: 0.075724603 | AC10: 0.21604168 | AD10: 0.26489173 | AE10: -0.18248798 | AG10: -0.15045984 | AI10: 0.13524701 | AJ10: 0.14874249 | AK10: 0.079087285 | AL10: 0.12357387 | AM10: 0.094808687 | AN10: 0.22058212 | AO10: 0.031076171 | AQ10: 0.10347469 | AS10: 0.083426251 | AT10: 0.17863142 | AX10: 0.11947623 | AY10: 0.12153925 | AZ10: 0.1528321 | BB10: 0.037667223 | BC10: 0.11971337 | BD10: 0.079616439 | BE10: 0.037335983 | BF10: 0.20570397 | BG10: 0.21627171 | BH10: 0.038301973 | BI10: 0.031280214 | BJ10: 0.10985387 | BK10: 0.25839888 | BL10: 0.11403231 | BN10: 0.037332147 | BO10: -0.0034052025 | BP10: 0.1945506 | BQ10: 0.18572923 | BT10: 0.061070153 | BW10: 0.055607287 | BX10: 0.18211345 | BY10: 0.090870196 | BZ10: 0.20569697 | CA10: 0.08389477 | CB10: 0.18049508 | CC10: 0.24675775 | CD10: 0.090180344 | CE10: 0.050012121 | CF10: 0.16743803 | CH10: -0.099977309 | CJ10: 0.13526435 | CK10: 0.1534026 | CL10: 0.13968537 | CN10: 0.13697891 | CP10: -0.16002883
A11: k_act_inact_ratio | B11: 0.88376099 | D11: 1.2525901 | E11: 1.0681363 | F11: 1.7810977 | I11: 0.43090824 | J11: 0.66721778 | K11: 0.88261856 | L11: 0.73588112 | M11: 0.97002603 | N11: 0.46706783 | O11: 0.8022279 | Q11: 1.3047135 | R11: 0.87974226 | T11: 0.90649421 | U11: 0.81251489 | X11: 0.48722569 | Y11: 0.86064261 | Z11: 0.70772479 | AA11: 1.0784257 | AB11: 1.0213779 | AC11: 0.73180333 | AD11: 0.85048299 | AE11: 0.64346482 | AG11: 2.0033054 | AI11: 1.2309222 | AJ11: 1.2315183 | AK11: 1.5556398 | AL11: 1.0095806 | AM11: 1.1828648 | AN11: 0.65449759 | AO11: 0.868894 | AQ11: 0.95670207 | AS11: 0.92951128 | AT11: 1.204728 | AX11: 0.77173124 | AY11: 1.2431394 | AZ11: 0.99599135 | BB11: 0.82913813 | BC11: 0.82799163 | BD11: 1.3105502 | BE11: 0.7413739 | BF11: 1.4416633 | BG11: 0.93647952 | BH11: 1.1289323 | BI11: 1.2550607 | BJ11: 4.9883456 | BK11: 0.69376275 | BL11: 0.95303843 | BN11: 0.73754856 | BO11: 3.2395084 | BP11: 0.46788694 | BQ11: 0.47646185 | BT11: 1.6668969 | BW11: 1.6506613 | BX11: 0.95414349 | BY11: 1.4087121 | BZ11: 0.8982963 | CA11: 1.0435611 | CB11: 0.54863398 | CC11: 1.0413236 | CD11: 1.1379669 | CE11: 1.349291 | CF11: 0.65407265 | CH11: 1.4060273 | CJ11: 0.82618337 | CK11: 1.0239905 | CL11: 1.0239067 | CN11: 1.2900002 | CP11: 1.7171643
A12: I_max_current_density | B12: -1083.4116 | C12: -316.72758 | D12: -228.12117 | E12: -595.72975 | F12: -822.36902 | G12: -505.84662 | H12: -327.53381 | I12: -366.84891 | J12: -969.31199 | K12: -508.80304 | L12: -105.93359 | M12: -433.45572 | N12: -180.17218 | O12: -206.23072 | P12: -268.44231 | Q12: -154.9775 | R12: -212.62512 | S12: -204.28477 | T12: -135.17437 | U12: -238.92971 | V12: -110.96289 | W12: -421.51422 | X12: -146.37058 | Y12: -223.98672 | Z12: -248.20879 | AA12: -347.04925 | AB12: -340.80464 | AC12: -57.275416 | AD12: -352.16318 | AE12: -92.013773 | AF12: -65.704294 | AG12: -261.54702 | AH12: -67.583905 | AI12: -159.14069 | AJ12: -138.88617 | AK12: -84.411819 | AL12: -106.85205 | AM12: -194.74397 | AN12: -77.728871 | AO12: -68.086536 | AP12: -30.698822 | AQ12: -112.27736 | AR12: -25.962288 | AS12: -23.244472 | AT12: -57.608602 | AU12: -21.605055 | AV12: -89.718528 | AW12: -18.195803 | AX12: -41.270992 | AY12: -33.220616 | AZ12: -27.241381 | BA12: -32.88586 | BB12: -36.182465 | BC12: -132.08839 | BD12: -24.547995 | BE12: -278.99706 | BF12: -317.17217 | BG12: -190.59813 | BH12: -353.37388 | BI12: -139.87579 | BJ12: -84.63518 | BK12: -62.340107 | BL12: -83.431577 | BM12: -94.104325 | BN12: -40.936519 | BO12: -128.11198 | BP12: -24.989662 | BQ12: -13.343705 | BR12: -71.789579 | BS12: -58.839443 | BT12: -22.181283 | BU12: -188.30988 | BV12: -66.498674 | BW12: -61.917711 | BX12: -86.945365 | BY12: -116.50274 | BZ12: -369.05681 | CA12: -118.67455 | CB12: -100.50035 | CC12: -126.76929 | CD12: -50.903207 | CE12: -80.608738 | CF12: -13.143409 | CG12: -55.402421 | CH12: -57.31447 | CI12: -24.311521 | CJ12: -42.659623 | CK12: -77.892754 | CL12: -24.996315 | CM12: -8.7681507 | CN12: -57.868413 | CO12: -24.270425 | CP12: -42.227423 | CQ12: -89.82481
A13: lnImax | B13: =LN(-B12) -> 6.9878703 | C13: =LN(-C12) -> 5.758042 | D13: =LN(-D12) -> 5.4298769 | E13: =LN(-E12) -> 6.3897871 | F13: =LN(-F12) -> 6.7121892 | G13: =LN(-G12) -> 6.2262335 | H13: =LN(-H12) -> 5.7915913 | I13: =LN(-I12) -> 5.9049501 | ... CQ13: =LN(-CQ12) -> 4.4978612

Sheet Window_Current
A1: Collector | B1: REdC | C1: REdC | D1: REdC | E1: REdC | F1: REdC | G1: REdC | H1: REdC | I1: REdC | J1: REdC | K1: REdC | L1: REdC | M1: REdC | N1: REdC | O1: REdC | P1: REdC | Q1: REdC | R1: REdC | S1: REdC | T1: REdC | U1: REdC | V1: REdC | W1: REdC | X1: REdC | Y1: REdC | Z1: REdC | AA1: REdC | AB1: REdC | AC1: REdC | AD1: REdC | AE1: REdC | AF1: REdC | AG1: REdC | AH1: REdC | AI1: REdC | AJ1: REdC | AK1: REdC | AL1: REdC | AM1: REdC | AN1: REdC | AO1: REdC | AP1: REdC | AQ1: REdC | AR1: REdC | AS1: REdC | AT1: REdC | AU1: REdC | AV1: REdC | AW1: REdC | AX1: REdC | AY1: REdC | AZ1: REdC | BA1: REdC | BB1: REdC | BC1: REdC | BD1: REdC | BE1: REdC | BF1: REdC | BG1: REdC | BH1: REdC | BI1: REdC | BJ1: REdC | BK1: REdC | BL1: REdC | BM1: REdC | BN1: REdC | BO1: REdC | BP1: REdC | BQ1: REdC | BR1: REdC
A2: Filename_act | B2: WT1_REdC_IV_18704034 | C2: WT3_REdC_IV_17728035 Final | D2: WT4_REdC_IV_18705015 | E2: WT5_REdC_IV_17728025 Final | F2: WT8_REdC_IV | G2: WT9_REdC_IV_17504013 Final | H2: WT10_REdC_IV_1.26.2018 WT cell 2 IV' -120 conditioning | I2: WT11_REdC_IV_17723017 | J2: WT12_REdC_IV_17721049 Final filtered | K2: WT13_REdC_IV_17723001 | L2: WT14_REdC_IV_19n15007 | M2: WT16_REdC_IV_18705033 | N2: WT17_REdC_IV_17721059 | O2: WT20_REdC_IV_18115016 | P2: WT21_REdC_IV_19o30001 (-80:0),WT21_REdC_IV_19o30004(10:+80) | Q2: WT24_REdC_IV_18705003(-80:10),WT24_REdC_IV_18705002(20:+80) | R2: WT25_REdC_IV_18704045 | S2: WT26_REdC_IV_17809014 | T2: WT27_REdC_IV_1.23.2018 IV cell 1 WT | U2: WT28_REdC_IV_1.23.2018 IV cell 1 WT | V2: WT29_REdC_IV_18o19010 | W2: WT30_REdC_IV_1.26.2018 WT cell 1 IV p8 20 sweeps | X2: WT31_REdC_IV_18o07001 | Y2: WT33_REdC_IV_17728018 | Z2: WT38_REdC_IV_19o21015 | AA2: WT39_REdC_IV_17429002 | AB2: WT40_REdC_IV_17810003 | AC2: WT43_REdC_IV_1.26.2018 WT cell 4 IV | AD2: WT44_REdC_IV_1.14.2018 IV cell 2 NaV1.4 wt | AE2: WT47_REdC_IV_19911011 | AF2: WT48_REdC_IV_19n06031 | AG2: WT50_REdC_IV_19n06011 | AH2: WT54_REdC_IV_1.19.2018 IV cell 1 WT | AI2: WT63_REdC_IV_19n07011 | AJ2: WT66_REdC_IV_18704009 | AK2: WT69_REdC_IV_18o18036 | AL2: WT74_REdC_IV_0003.abf | AM2: WT75_REdC_IV_0015.abf | AN2: WT76_REdC_IV_0012.abf | AO2: EPN1_REdC_IV_17725093.abf | AP2: EPN2_REdC_IV_17725017.abf | AQ2: EPN3_REdC_IV_18115045.abf | AR2: EPN4_REdC_IV_IV cell 2 NaV1.4 EPN.abf | AS2: EPN5_REdC_IV_17725043.abf | AT2: EPN6_REdC_IV_1.14.2018 IV cell 1 NaV1.4 EPN.abf | AU2: EPN7_REdC_IV_17718015.abf | AV2: EPN9_REdC_IV_17725067.abf | AW2: EPN11_REdC_IV_17725020.abf | AX2: EPN12_REdC_IV_1.19.2018 IV cell 1 EPN'.abf | AY2: EPN13_REdC_IV_2016_09_30_0015.abf | AZ2: EPN14_REdC_IV_17725071.abf | BA2: EPN18_REdC_IV_0012.abf | BB2: LVNV1_REdC_IV_17724088.abf | BC2: LVNV2_REdC_IV_17724059.abf;LVNV2_REdC_IV_17724048.abf;LVNV2_REdC_IV_17724046.abf | BD2: LVNV3_REdC_IV_17726022.abf | BE2: LVNV4_REdC_IV_17429000.abf | BF2: LVNV5_REdC_IV_17724073.abf | BG2: LVNV6_REdC_IV_19915011.abf | BH2: LVNV7_REdC_IV_19d06007.abf | BI2: LVNV8_REdC_IV_17724003.abf;LVNV8_REdC_IV_17724001.abf | BJ2: LVNV9_REdC_IV_17724034.abf | BK2: LVNV10_REdC_IV_17726060.abf;LVNV10_REdC_IV_17726061.abf | BL2: LVNV12_REdC_IV_19912002.abf | BM2: LVNV14_REdC_IV_17726099.abf;LVNV14_REdC_IV_17726072.abf;LVNV14_REdC_IV_17726074.abf;LVNV14_REdC_IV_17726083.abf;LVNV14_REdC_IV_17726088.abf;LVNV14_REdC_IV_17726095.abf;LVNV14_REdC_IV_17726098.abf;LVNV14_REdC_IV_17726100.abf | BN2: LVNV15_REdC_IV_17724016.abf | BO2: LVNV16_REdC_IV_17726035.abf | BP2: LVNV18_REdC_IV_19911028.abf;LVNV18_REdC_IV_19911026.abf;LVNV18_REdC_IV_19911027.abf;LVNV18_REdC_IV_19911029.abf | BQ2: LVNV20_REdC_IV_17726011.abf
A3: Filename_inact | B3: WT1_REdC_fSSI_18704040 | C3: WT3_REdC_fSSI_17728036 | D3: WT4_REdC_fSSI_18705016 | E3: WT5_REdC_fSSI_17728026 | F3: WT8_REdC_fSSI_1.23.2018 fSSI cell 2 WT | G3: WT9_REdC_fSSI_17504014 | H3: WT10_REdC_fSSI_1.26.2018 WT cell 2 fSSI from -120 | I3: WT11_REdC_fSSI_17723028 | J3: WT12_REdC_fSSI_17721037 | K3: WT13_REdC_fSSI_17723002 | L3: WT14_REdC_fSSI_19n15001 | M3: WT16_REdC_fSSI_18705034 | N3: WT17_REdC_fSSI_17721062 | O3: WT20_REdC_fSSI_18115015 | P3: WT21_REdC_fSSI_19o30003 | Q3: WT24_REdC_fSSI_18705004 | R3: WT25_REdC_fSSI_18704046 | S3: WT26_REdC_fSSI_17809018 | T3: WT27_REdC_fSSI_1.23.2018 fSSI cell 1 WT | U3: WT28_REdC_fSSI_1.23.2018 fSSI cell 1 WT | V3: WT29_REdC_fSSI_18o19011 | W3: WT30_REdC_fSSI_1.26.2018 WT cell 1 Fssi | X3: WT31_REdC_fSSI_18o07002 | Y3: WT33_REdC_fSSI_17728019 | Z3: WT38_REdC_fSSI_19o21003 | AA3: WT39_REdC_fSSI_17429003 | AB3: WT40_REdC_fSSI_17810004 | AC3: WT43_REdC_fSSI_1.26.2018 WT cell 4 fSSI | AD3: WT44_REdC_fSSI_1.14.2018 fSSI cell 2 NaV1.4 wt | AE3: WT47_REdC_fSSI_19911006 | AF3: WT48_REdC_fSSI_19n06033 | AG3: WT50_REdC_fSSI_19n06001 | AH3: WT54_REdC_fSSI_1.19.2018 fSSI cell 1 WT | AI3: WT63_REdC_fSSI_19n07001 | AJ3: WT66_REdC_fSSI_18704010 | AK3: WT69_REdC_fSSI_18o19004 | AL3: WT74_REdC_capac_0000.abf | AM3: WT75_REdC_capac_0000 | AN3: WT76_REdC_fSSI_0011.abf | AO3: EPN1_REdC_fSSI_17725094.abf | AP3: EPN2_REdC_fSSI_17725003.abf | AQ3: EPN3_REdC_fSSI_18115041.abf | AR3: EPN4_REdC_fSSI_fSSI cell 2 NaV1.4 EPN.abf | AS3: EPN5_REdC_fSSI_17725042.abf | AT3: EPN6_REdC_fSSI_1.14.2018 fSSI cell 1 NaV1.4 EPN.abf | AU3: EPN7_REdC_fSSI_17718002.abf | AV3: EPN9_REdC_fSSI_17725069.abf | AW3: EPN11_REdC_fSSI_17725022.abf | AX3: EPN12_REdC_fSSI_1.19.2018 fSSI cell 1 EPN.abf | AY3: EPN13_REdC_fSSI_2016_09_30_0008.abf | AZ3: EPN14_REdC_fSSI_17725073.abf | BA3: EPN18_REdC_fSSI_0008.abf | BB3: LVNV1_REdC_fSSI_17724087.abf | BC3: LVNV2_REdC_fSSI_17724049.abf | BD3: LVNV3_REdC_fSSI_17726025.abf | BE3: LVNV4_REdC_fSSI_17429003.abf | BF3: LVNV5_REdC_fSSI_17724076.abf | BG3: LVNV6_REdC_fSSI_19915014.abf | BH3: LVNV7_REdC_fSSI_19d06005.abf | BI3: LVNV8_REdC_fSSI_17724004.abf | BJ3: LVNV9_REdC_fSSI_17724035.abf | BK3: LVNV10_REdC_fSSI_17726051.abf | BL3: LVNV12_REdC_fSSI_19912003.abf | BM3: LVNV14_REdC_fSSI_17726075.abf;LVNV14_REdC_fSSI_17726087.abf;LVNV14_REdC_fSSI_17726094.abf | BN3: LVNV15_REdC_fSSI_17724017.abf | BO3: LVNV16_REdC_fSSI_17726037.abf | BP3: LVNV18_REdC_fSSI_19911030.abf | BQ3: LVNV20_REdC_fSSI_17726012.abf
A4: Genotype | B4: WT | C4: WT | D4: WT | E4: WT | F4: WT | G4: WT | H4: WT | I4: WT | J4: WT | K4: WT | L4: WT | M4: WT | N4: WT | O4: WT | P4: WT | Q4: WT | R4: WT | S4: WT | T4: WT | U4: WT | V4: WT | W4: WT | X4: WT | Y4: WT | Z4: WT | AA4: WT | AB4: WT | AC4: WT | AD4: WT | AE4: WT | AF4: WT | AG4: WT | AH4: WT | AI4: WT | AJ4: WT | AK4: WT | AL4: WT | AM4: WT | AN4: WT | AO4: EPN | AP4: EPN | AQ4: EPN | AR4: EPN | AS4: EPN | AT4: EPN | AU4: EPN | AV4: EPN | AW4: EPN | AX4: EPN | AY4: EPN | AZ4: EPN | BA4: EPN | BB4: LVNV | BC4: LVNV | BD4: LVNV | BE4: LVNV | BF4: LVNV | BG4: LVNV | BH4: LVNV | BI4: LVNV | BJ4: LVNV | BK4: LVNV | BL4: LVNV | BM4: LVNV | BN4: LVNV | BO4: LVNV | BP4: LVNV | BQ4: LVNV
A5: CellID | B5: WT1 | C5: WT3 | D5: WT4 | E5: WT5 | F5: WT8 | G5: WT9 | H5: WT10 | I5: WT11 | J5: WT12 | K5: WT13 | L5: WT14 | M5: WT16 | N5: WT17 | O5: WT20 | P5: WT21 | Q5: WT24 | R5: WT25 | S5: WT26 | T5: WT27 | U5: WT28 | V5: WT29 | W5: WT30 | X5: WT31 | Y5: WT33 | Z5: WT38 | AA5: WT39 | AB5: WT40 | AC5: WT43 | AD5: WT44 | AE5: WT47 | AF5: WT48 | AG5: WT50 | AH5: WT54 | AI5: WT63 | AJ5: WT66 | AK5: WT69 | AL5: WT74 | AM5: WT75 | AN5: WT76 | AO5: EPN1 | AP5: EPN2 | AQ5: EPN3 | AR5: EPN4 | AS5: EPN5 | AT5: EPN6 | AU5: EPN7 | AV5: EPN9 | AW5: EPN11 | AX5: EPN12 | AY5: EPN13 | AZ5: EPN14 | BA5: EPN18 | BB5: LVNV1 | BC5: LVNV2 | BD5: LVNV3 | BE5: LVNV4 | BF5: LVNV5 | BG5: LVNV6 | BH5: LVNV7 | BI5: LVNV8 | BJ5: LVNV9 | BK5: LVNV10 | BL5: LVNV12 | BM5: LVNV14 | BN5: LVNV15 | BO5: LVNV16 | BP5: LVNV18 | BQ5: LVNV20
A6: V_act_Erev | B6: -11.893189 | C6: -13.113383 | D6: -14.492698 | E6: -7.2988876 | F6: -24.776988 | G6: -12.295355 | H6: -10.347405 | I6: -9.4066368 | J6: -16.731332 | K6: -22.439747 | L6: -13.95828 | M6: -8.1928835 | N6: -4.2792807 | O6: -10.667967 | P6: -14.49881 | Q6: -6.2567251 | R6: -10.897064 | S6: -6.1586836 | T6: -5.5955477 | U6: -6.072556 | V6: -12.354167 | W6: -13.411517 | X6: 6.2185301 | Y6: 7.2454954 | Z6: -8.3078498 | AA6: -11.596596 | AB6: -4.7036246 | AC6: -8.9175 | AD6: -7.8455289 | AE6: -13.523399 | AF6: -3.76205 | AG6: -7.2084227 | AH6: -12.5865 | AI6: -5.310725 | AJ6: -4.36795 | AK6: -11.971919 | AL6: -4.105028 | AM6: -7.4050458 | AN6: -2.2405886 | AO6: -3.224202 | AP6: -12.063375 | AQ6: -17.510011 | AR6: -5.8318676 | AS6: -4.4054419 | AT6: -6.9000827 | AU6: -11.89204 | AV6: -5.2631182 | AW6: -1.6437874 | AX6: -5.2489907 | AY6: -12.191047 | AZ6: -13.376909 | BA6: -0.76719344 | BB6: -3.7037154 | BC6: -13.950467 | BD6: -6.7575734 | BE6: -17.517262 | BF6: -3.1999735 | BG6: -8.9048019 | BH6: -15.142334 | BI6: -6.3117674 | BJ6: -6.1017701 | BK6: -10.86271 | BL6: 4.0810617 | BM6: -8.3455382 | BN6: -8.7834957 | BO6: -6.0719264 | BP6: -3.8530842 | BQ6: -5.256282
A7: k_act_Erev | B7: 6.4829144 | C7: 7.0134718 | D7: 5.2872971 | E7: 9.7912631 | F7: 3.6054903 | G7: 4.2309302 | H7: 4.4851231 | I7: 6.6388003 | J7: 4.7195387 | K7: 3.8166171 | L7: 5.206627 | M7: 6.5853558 | N7: 6.6405857 | O7: 9.6830389 | P7: 4.7881119 | Q7: 5.9690346 | R7: 6.3728018 | S7: 6.4196143 | T7: 8.9916863 | U7: 8.0157498 | V7: 5.8942386 | W7: 2.7655786 | X7: 6.4011585 | Y7: 9.4502473 | Z7: 7.8713322 | AA7: 7.2134055 | AB7: 7.5708541 | AC7: 6.7669796 | AD7: 8.1187186 | AE7: 6.5533518 | AF7: 5.4196226 | AG7: 6.324599 | AH7: 9.6662384 | AI7: 6.9319466 | AJ7: 14.288264 | AK7: 8.8055881 | AL7: 9.4084188 | AM7: 6.6223184 | AN7: 8.5304158 | AO7: 8.5439597 | AP7: 3.3832945 | AQ7: 6.9329192 | AR7: 7.2694205 | AS7: 7.6395251 | AT7: 14.27214 | AU7: 6.6809011 | AV7: 7.0121505 | AW7: 7.9633693 | AX7: 8.1680531 | AY7: 5.2496131 | AZ7: 3.7302858 | BA7: 10.506408 | BB7: 7.4671515 | BC7: 7.4181175 | BD7: 8.2821358 | BE7: 4.0079812 | BF7: 9.8466314 | BG7: 5.5988693 | BH7: 7.4022557 | BI7: 7.4941831 | BJ7: 10.492991 | BK7: 7.8308324 | BL7: 8.8195383 | BM7: 8.4795329 | BN7: 5.7751146 | BO7: 7.2650782 | BP7: 10.846425 | BQ7: 14.502148
A8: V_inact | B8: -61.810949 | C8: -55.892692 | D8: -56.233799 | E8: -56.913929 | F8: -65.497748 | G8: -70.671663 | H8: -64.871759 | I8: -62.242112 | J8: -58.611412 | K8: -58.859281 | L8: -52.754045 | M8: -55.598744 | N8: -52.885693 | O8: -66.052187 | P8: -60.972634 | Q8: -52.294763 | R8: -63.342266 | S8: -73.829378 | T8: -80.63667 | U8: -80.618315 | V8: -54.180115 | W8: -66.72168 | X8: -42.800769 | Y8: -61.018268 | Z8: -52.511469 | AA8: -65.294088 | AB8: -53.889759 | AC8: -74.8926 | AD8: -65.772452 | AE8: -59.592561 | AF8: -52.933589 | AG8: -56.858692 | AH8: -69.180191 | AI8: -55.516487 | AJ8: -51.44691 | AK8: -63.622345 | AL8: -56.060698 | AM8: -57.283956 | AN8: -53.579678 | AO8: -66.612182 | AP8: -59.593911 | AQ8: -71.529866 | AR8: -53.025927 | AS8: -54.535528 | AT8: -68.194174 | AU8: -50.132349 | AV8: -57.387775 | AW8: -51.084895 | AX8: -76.922049 | AY8: -58.644583 | AZ8: -44.856575 | BA8: -53.43682 | BB8: -51.705697 | BC8: -57.383966 | BD8: -58.836399 | BE8: -65.18164 | BF8: -68.748043 | BG8: -50.389338 | BH8: -62.798126 | BI8: -59.242373 | BJ8: -59.971943 | BK8: -53.813671 | BL8: -63.252571 | BM8: -54.301519 | BN8: -57.781133 | BO8: -57.851471 | BP8: -46.169783 | BQ8: -55.009096
